Workbook

Sheet Setup
A1: Team | B1: Role | C1: Players
A2: Steelers | B2: C | E2: 1 | F2: Make a copy of this Scoresheet and keep the link to that copy
B3: OP1 | E3: 2 | F3: Fill OP1, OP2, DP1, and DP2 for each team with player names
B4: OP2 | E4: 3 | F4: Fill Captain (C) for each team with OP1, OP2, DP1, or DP2
B5: DP1 | E5: 4 | F5: Move to Game 1 sheet and start filling in results
B6: DP2 | E6: If you get a Protection Error, you probably shouldn't touch that cell
A7: Ravens | B7: C | E7: If you must unprotect this sheet/workbook, the password is AMQ
B8: OP1
B9: OP2
B10: DP1
B11: DP2
A12: Browns | B12: C
B13: OP1
B14: OP2
B15: DP1
B16: DP2
A17: Bengals | B17: C
B18: OP1
B19: OP2
B20: DP1
B21: DP2
A22: Packers | B22: C
B23: OP1
B24: OP2
B25: DP1
B26: DP2
A27: Vikings | B27: C
B28: OP1
B29: OP2
B30: DP1
B31: DP2
A32: Lions | B32: C
B33: OP1
B34: OP2
B35: DP1
B36: DP2
A37: Bears | B37: C
B38: OP1
B39: OP2
B40: DP1
...

Sheet Game 1
A1: Song | B1: Poss. | C1: Poss. | D1: Ravens | I1: Steelers | N1: TDIFF | O1: DIFF | P1: Result | Q1: Score | S1: Winner
D2: C | E2: OP1 | F2: OP2 | G2: DP1 | H2: DP2 | I2: OP1 | J2: OP2 | K2: DP1 | L2: DP2 | M2: C | Q2: =D1 -> Ravens | R2: =I1 -> Steelers | U2: 1 | V2: Change E1 and I1 to the right Away and Home teams
A3: Regulation: 16 Watched Equal, 4 Random songs. Mercy Rule if Score Deficit > Remaining Songs × 8 | U3: 2 | V3: Fill Column E to L with 1 for whoever gets each song right
A4: 1 | B4: 0 | C4: =IF(B4=0,D$1,I$1) -> Ravens | D4: {=_xlfn.SWITCH(VLOOKUP(D1,Setup!A:C,3,FALSE),"OP1",1,"OP2",2,"DP1",3,"DP2",4,1)} -> 1 | M4: {=_xlfn.SWITCH(VLOOKUP(I1,Setup!A:C,3,FALSE),"OP1",1,"OP2",2,"DP1",3,"DP2",4,1)} -> 1 | N4: {=IF(ABS((SUM(E4:H4)+INDEX(E4:H4,1,$D$4))-(SUM(I4:L4)+INDEX(I4:L4,1,$M$4)))>3,(1-2*B4)*((SUM(E4:H4)+INDEX(E4:H4,1,$D$4))-(SUM(I4:L4)+INDEX(I4:L4,1,$M$4))),"")} | O4: {=IF(N4<>"",N4,IF(B4=0,(E4+F4+IF($D$4<=2,INDEX(E4:H4,1,$D$4),0))-(K4+L4+IF($M$4>=3,INDEX(I4:L4,1,$M$4),0)),(I4+J4+IF($M$4<=2,INDEX(I4:L4,1,$M$4),0))-(G4+H4+IF($D$4>=3,INDEX(E4:H4,1,$D$4),0))))} -> 0 | P4: =IF(O4>3,"Onside Kick",IF(O4=3,"TD + 2PC",IF(O4=2,"Touchdown",IF(O4=1,"Field Goal",IF(O4>-2,"Punt",IF(O4=-2,"Safety",IF(O4=-3,"Pick Six","House Call"))))))) -> Punt | Q4: =IF(O4>1,IF(O4=3,8,7),IF(O4=1,3,0)) -> 0 | R4: =IF(O4>-2,0,IF(O4=-2,2,IF(O4=-3,6,7))) -> 0 | S4: =IF(OR(S3=D$1,S3=I$1),S3,IF(ABS(Q4-R4)>(20-A4)*8,IF(Q4>R4,D$1,I$1),"TBD")) -> TBD | U4: 3 | V4: Continue playing until either happens:
A5: 2 | B5: =IF(AND(N4<>"",N4>3),B4,1-B4) -> 1 | C5: =IF(B5=0,D$1,I$1) -> Steelers | N5: {=IF(ABS((SUM(E5:H5)+INDEX(E5:H5,1,$D$4))-(SUM(I5:L5)+INDEX(I5:L5,1,$M$4)))>3,(1-2*B5)*((SUM(E5:H5)+INDEX(E5:H5,1,$D$4))-(SUM(I5:L5)+INDEX(I5:L5,1,$M$4))),"")} | O5: {=IF(N5<>"",N5,IF(B5=0,(E5+F5+IF($D$4<=2,INDEX(E5:H5,1,$D$4),0))-(K5+L5+IF($M$4>=3,INDEX(I5:L5,1,$M$4),0)),(I5+J5+IF($M$4<=2,INDEX(I5:L5,1,$M$4),0))-(G5+H5+IF($D$4>=3,INDEX(E5:H5,1,$D$4),0))))} -> 0 | P5: =IF(O5>3,"Onside Kick",IF(O5=3,"TD + 2PC",IF(O5=2,"Touchdown",IF(O5=1,"Field Goal",IF(O5>-2,"Punt",IF(O5=-2,"Safety",IF(O5=-3,"Pick Six","House Call"))))))) -> Punt | Q5: =IF(B5=0,Q4+IF(O5>1,IF(O5=3,8,7),IF(O5=1,3,0)),Q4+IF(O5>-2,0,IF(O5=-2,2,IF(O5=-3,6,7)))) -> 0 | R5: =IF(B5=0,R4+IF(O5>-2,0,IF(O5=-2,2,IF(O5=-3,6,7))),R4+IF(O5>1,IF(O5=3,8,7),IF(O5=1,3,0))) -> 0 | S5: =IF(OR(S4=D$1,S4=I$1),S4,IF(ABS(Q5-R5)>(20-A5)*8,IF(Q5>R5,D$1,I$1),"TBD")) -> TBD | V5: 1 | W5: You run out of songs, or
A6: 3 | B6: =IF(AND(N5<>"",N5>3),B5,1-B5) -> 0 | C6: =IF(B6=0,D$1,I$1) -> Ravens | N6: {=IF(ABS((SUM(E6:H6)+INDEX(E6:H6,1,$D$4))-(SUM(I6:L6)+INDEX(I6:L6,1,$M$4)))>3,(1-2*B6)*((SUM(E6:H6)+INDEX(E6:H6,1,$D$4))-(SUM(I6:L6)+INDEX(I6:L6,1,$M$4))),"")} | O6: {=IF(N6<>"",N6,IF(B6=0,(E6+F6+IF($D$4<=2,INDEX(E6:H6,1,$D$4),0))-(K6+L6+IF($M$4>=3,INDEX(I6:L6,1,$M$4),0)),(I6+J6+IF($M$4<=2,INDEX(I6:L6,1,$M$4),0))-(G6+H6+IF($D$4>=3,INDEX(E6:H6,1,$D$4),0))))} -> 0 | P6: =IF(O6>3,"Onside Kick",IF(O6=3,"TD + 2PC",IF(O6=2,"Touchdown",IF(O6=1,"Field Goal",IF(O6>-2,"Punt",IF(O6=-2,"Safety",IF(O6=-3,"Pick Six","House Call"))))))) -> Punt | Q6: =IF(B6=0,Q5+IF(O6>1,IF(O6=3,8,7),IF(O6=1,3,0)),Q5+IF(O6>-2,0,IF(O6=-2,2,IF(O6=-3,6,7)))) -> 0 | R6: =IF(B6=0,R5+IF(O6>-2,0,IF(O6=-2,2,IF(O6=-3,6,7))),R5+IF(O6>1,IF(O6=3,8,7),IF(O6=1,3,0))) -> 0 | S6: =IF(OR(S5=D$1,S5=I$1),S5,IF(ABS(Q6-R6)>(20-A6)*8,IF(Q6>R6,D$1,I$1),"TBD")) -> TBD | V6: 2 | W6: Winner column on current Song row is not TBD
A7: 4 | B7: =IF(AND(N6<>"",N6>3),B6,1-B6) -> 1 | C7: =IF(B7=0,D$1,I$1) -> Steelers | N7: {=IF(ABS((SUM(E7:H7)+INDEX(E7:H7,1,$D$4))-(SUM(I7:L7)+INDEX(I7:L7,1,$M$4)))>3,(1-2*B7)*((SUM(E7:H7)+INDEX(E7:H7,1,$D$4))-(SUM(I7:L7)+INDEX(I7:L7,1,$M$4))),"")} | O7: {=IF(N7<>"",N7,IF(B7=0,(E7+F7+IF($D$4<=2,INDEX(E7:H7,1,$D$4),0))-(K7+L7+IF($M$4>=3,INDEX(I7:L7,1,$M$4),0)),(I7+J7+IF($M$4<=2,INDEX(I7:L7,1,$M$4),0))-(G7+H7+IF($D$4>=3,INDEX(E7:H7,1,$D$4),0))))} -> 0 | P7: =IF(O7>3,"Onside Kick",IF(O7=3,"TD + 2PC",IF(O7=2,"Touchdown",IF(O7=1,"Field Goal",IF(O7>-2,"Punt",IF(O7=-2,"Safety",IF(O7=-3,"Pick Six","House Call"))))))) -> Punt | Q7: =IF(B7=0,Q6+IF(O7>1,IF(O7=3,8,7),IF(O7=1,3,0)),Q6+IF(O7>-2,0,IF(O7=-2,2,IF(O7=-3,6,7)))) -> 0 | R7: =IF(B7=0,R6+IF(O7>-2,0,IF(O7=-2,2,IF(O7=-3,6,7))),R6+IF(O7>1,IF(O7=3,8,7),IF(O7=1,3,0))) -> 0 | S7: =IF(OR(S6=D$1,S6=I$1),S6,IF(ABS(Q7-R7)>(20-A7)*8,IF(Q7>R7,D$1,I$1),"TBD")) -> TBD | U7: 4 | V7: Continue to the next Game scoresheet
A8: 5 | B8: =IF(AND(N7<>"",N7>3),B7,1-B7) -> 0 | C8: =IF(B8=0,D$1,I$1) -> Ravens | N8: {=IF(ABS((SUM(E8:H8)+INDEX(E8:H8,1,$D$4))-(SUM(I8:L8)+INDEX(I8:L8,1,$M$4)))>3,(1-2*B8)*((SUM(E8:H8)+INDEX(E8:H8,1,$D$4))-(SUM(I8:L8)+INDEX(I8:L8,1,$M$4))),"")} | O8: {=IF(N8<>"",N8,IF(B8=0,(E8+F8+IF($D$4<=2,INDEX(E8:H8,1,$D$4),0))-(K8+L8+IF($M$4>=3,INDEX(I8:L8,1,$M$4),0)),(I8+J8+IF($M$4<=2,INDEX(I8:L8,1,$M$4),0))-(G8+H8+IF($D$4>=3,INDEX(E8:H8,1,$D$4),0))))} -> 0 | P8: =IF(O8>3,"Onside Kick",IF(O8=3,"TD + 2PC",IF(O8=2,"Touchdown",IF(O8=1,"Field Goal",IF(O8>-2,"Punt",IF(O8=-2,"Safety",IF(O8=-3,"Pick Six","House Call"))))))) -> Punt | Q8: =IF(B8=0,Q7+IF(O8>1,IF(O8=3,8,7),IF(O8=1,3,0)),Q7+IF(O8>-2,0,IF(O8=-2,2,IF(O8=-3,6,7)))) -> 0 | R8: =IF(B8=0,R7+IF(O8>-2,0,IF(O8=-2,2,IF(O8=-3,6,7))),R7+IF(O8>1,IF(O8=3,8,7),IF(O8=1,3,0))) -> 0 | S8: =IF(OR(S7=D$1,S7=I$1),S7,IF(ABS(Q8-R8)>(20-A8)*8,IF(Q8>R8,D$1,I$1),"TBD")) -> TBD | V8: Swap Away and Home if you play the same team again
A9: 6 | B9: =IF(AND(N8<>"",N8>3),B8,1-B8) -> 1 | C9: =IF(B9=0,D$1,I$1) -> Steelers | N9: {=IF(ABS((SUM(E9:H9)+INDEX(E9:H9,1,$D$4))-(SUM(I9:L9)+INDEX(I9:L9,1,$M$4)))>3,(1-2*B9)*((SUM(E9:H9)+INDEX(E9:H9,1,$D$4))-(SUM(I9:L9)+INDEX(I9:L9,1,$M$4))),"")} | O9: {=IF(N9<>"",N9,IF(B9=0,(E9+F9+IF($D$4<=2,INDEX(E9:H9,1,$D$4),0))-(K9+L9+IF($M$4>=3,INDEX(I9:L9,1,$M$4),0)),(I9+J9+IF($M$4<=2,INDEX(I9:L9,1,$M$4),0))-(G9+H9+IF($D$4>=3,INDEX(E9:H9,1,$D$4),0))))} -> 0 | P9: =IF(O9>3,"Onside Kick",IF(O9=3,"TD + 2PC",IF(O9=2,"Touchdown",IF(O9=1,"Field Goal",IF(O9>-2,"Punt",IF(O9=-2,"Safety",IF(O9=-3,"Pick Six","House Call"))))))) -> Punt | Q9: =IF(B9=0,Q8+IF(O9>1,IF(O9=3,8,7),IF(O9=1,3,0)),Q8+IF(O9>-2,0,IF(O9=-2,2,IF(O9=-3,6,7)))) -> 0 | R9: =IF(B9=0,R8+IF(O9>-2,0,IF(O9=-2,2,IF(O9=-3,6,7))),R8+IF(O9>1,IF(O9=3,8,7),IF(O9=1,3,0))) -> 0 | S9: =IF(OR(S8=D$1,S8=I$1),S8,IF(ABS(Q9-R9)>(20-A9)*8,IF(Q9>R9,D$1,I$1),"TBD")) -> TBD | U9: 5 | V9: Report the link to your copy after the last game
A10: 7 | B10: =IF(AND(N9<>"",N9>3),B9,1-B9) -> 0 | C10: =IF(B10=0,D$1,I$1) -> Ravens | N10: {=IF(ABS((SUM(E10:H10)+INDEX(E10:H10,1,$D$4))-(SUM(I10:L10)+INDEX(I10:L10,1,$M$4)))>3,(1-2*B10)*((SUM(E10:H10)+INDEX(E10:H10,1,$D$4))-(SUM(I10:L10)+INDEX(I10:L10,1,$M$4))),"")} | O10: {=IF(N10<>"",N10,IF(B10=0,(E10+F10+IF($D$4<=2,INDEX(E10:H10,1,$D$4),0))-(K10+L10+IF($M$4>=3,INDEX(I10:L10,1,$M$4),0)),(I10+J10+IF($M$4<=2,INDEX(I10:L10,1,$M$4),0))-(G10+H10+IF($D$4>=3,INDEX(E10:H10,1,$D$4),0))))} -> 0 | P10: =IF(O10>3,"Onside Kick",IF(O10=3,"TD + 2PC",IF(O10=2,"Touchdown",IF(O10=1,"Field Goal",IF(O10>-2,"Punt",IF(O10=-2,"Safety",IF(O10=-3,"Pick Six","House Call"))))))) -> Punt | Q10: =IF(B10=0,Q9+IF(O10>1,IF(O10=3,8,7),IF(O10=1,3,0)),Q9+IF(O10>-2,0,IF(O10=-2,2,IF(O10=-3,6,7)))) -> 0 | R10: =IF(B10=0,R9+IF(O10>-2,0,IF(O10=-2,2,IF(O10=-3,6,7))),R9+IF(O10>1,IF(O10=3,8,7),IF(O10=1,3,0))) -> 0 | S10: =IF(OR(S9=D$1,S9=I$1),S9,IF(ABS(Q10-R10)>(20-A10)*8,IF(Q10>R10,D$1,I$1),"TBD")) -> TBD | U10: If you get a Protection Error, you probably shouldn't touch that cell
A11: 8 | B11: =IF(AND(N10<>"",N10>3),B10,1-B10) -> 1 | C11: =IF(B11=0,D$1,I$1) -> Steelers | N11: {=IF(ABS((SUM(E11:H11)+INDEX(E11:H11,1,$D$4))-(SUM(I11:L11)+INDEX(I11:L11,1,$M$4)))>3,(1-2*B11)*((SUM(E11:H11)+INDEX(E11:H11,1,$D$4))-(SUM(I11:L11)+INDEX(I11:L11,1,$M$4))),"")} | O11: {=IF(N11<>"",N11,IF(B11=0,(E11+F11+IF($D$4<=2,INDEX(E11:H11,1,$D$4),0))-(K11+L11+IF($M$4>=3,INDEX(I11:L11,1,$M$4),0)),(I11+J11+IF($M$4<=2,INDEX(I11:L11,1,$M$4),0))-(G11+H11+IF($D$4>=3,INDEX(E11:H11,1,$D$4),0))))} -> 0 | P11: =IF(O11>3,"Onside Kick",IF(O11=3,"TD + 2PC",IF(O11=2,"Touchdown",IF(O11=1,"Field Goal",IF(O11>-2,"Punt",IF(O11=-2,"Safety",IF(O11=-3,"Pick Six","House Call"))))))) -> Punt | Q11: =IF(B11=0,Q10+IF(O11>1,IF(O11=3,8,7),IF(O11=1,3,0)),Q10+IF(O11>-2,0,IF(O11=-2,2,IF(O11=-3,6,7)))) -> 0 | R11: =IF(B11=0,R10+IF(O11>-2,0,IF(O11=-2,2,IF(O11=-3,6,7))),R10+IF(O11>1,IF(O11=3,8,7),IF(O11=1,3,0))) -> 0 | S11: =IF(OR(S10=D$1,S10=I$1),S10,IF(ABS(Q11-R11)>(20-A11)*8,IF(Q11>R11,D$1,I$1),"TBD")) -> TBD | U11: If you must unprotect this sheet/workbook, the password is AMQ
A12: 9 | B12: =IF(AND(N11<>"",N11>3),B11,1-B11) -> 0 | C12: =IF(B12=0,D$1,I$1) -> Ravens | N12: {=IF(ABS((SUM(E12:H12)+INDEX(E12:H12,1,$D$4))-(SUM(I12:L12)+INDEX(I12:L12,1,$M$4)))>3,(1-2*B12)*((SUM(E12:H12)+INDEX(E12:H12,1,$D$4))-(SUM(I12:L12)+INDEX(I12:L12,1,$M$4))),"")} | O12: {=IF(N12<>"",N12,IF(B12=0,(E12+F12+IF($D$4<=2,INDEX(E12:H12,1,$D$4),0))-(K12+L12+IF($M$4>=3,INDEX(I12:L12,1,$M$4),0)),(I12+J12+IF($M$4<=2,INDEX(I12:L12,1,$M$4),0))-(G12+H12+IF($D$4>=3,INDEX(E12:H12,1,$D$4),0))))} -> 0 | P12: =IF(O12>3,"Onside Kick",IF(O12=3,"TD + 2PC",IF(O12=2,"Touchdown",IF(O12=1,"Field Goal",IF(O12>-2,"Punt",IF(O12=-2,"Safety",IF(O12=-3,"Pick Six","House Call"))))))) -> Punt | Q12: =IF(B12=0,Q11+IF(O12>1,IF(O12=3,8,7),IF(O12=1,3,0)),Q11+IF(O12>-2,0,IF(O12=-2,2,IF(O12=-3,6,7)))) -> 0 | R12: =IF(B12=0,R11+IF(O12>-2,0,IF(O12=-2,2,IF(O12=-3,6,7))),R11+IF(O12>1,IF(O12=3,8,7),IF(O12=1,3,0))) -> 0 | S12: =IF(OR(S11=D$1,S11=I$1),S11,IF(ABS(Q12-R12)>(20-A12)*8,IF(Q12>R12,D$1,I$1),"TBD")) -> TBD
A13: 10 | B13: =IF(AND(N12<>"",N12>3),B12,1-B12) -> 1 | C13: =IF(B13=0,D$1,I$1) -> Steelers | N13: {=IF(ABS((SUM(E13:H13)+INDEX(E13:H13,1,$D$4))-(SUM(I13:L13)+INDEX(I13:L13,1,$M$4)))>3,(1-2*B13)*((SUM(E13:H13)+INDEX(E13:H13,1,$D$4))-(SUM(I13:L13)+INDEX(I13:L13,1,$M$4))),"")} | O13: {=IF(N13<>"",N13,IF(B13=0,(E13+F13+IF($D$4<=2,INDEX(E13:H13,1,$D$4),0))-(K13+L13+IF($M$4>=3,INDEX(I13:L13,1,$M$4),0)),(I13+J13+IF($M$4<=2,INDEX(I13:L13,1,$M$4),0))-(G13+H13+IF($D$4>=3,INDEX(E13:H13,1,$D$4),0))))} -> 0 | P13: =IF(O13>3,"Onside Kick",IF(O13=3,"TD + 2PC",IF(O13=2,"Touchdown",IF(O13=1,"Field Goal",IF(O13>-2,"Punt",IF(O13=-2,"Safety",IF(O13=-3,"Pick Six","House Call"))))))) -> Punt | Q13: =IF(B13=0,Q12+IF(O13>1,IF(O13=3,8,7),IF(O13=1,3,0)),Q12+IF(O13>-2,0,IF(O13=-2,2,IF(O13=-3,6,7)))) -> 0 | R13: =IF(B13=0,R12+IF(O13>-2,0,IF(O13=-2,2,IF(O13=-3,6,7))),R12+IF(O13>1,IF(O13=3,8,7),IF(O13=1,3,0))) -> 0 | S13: =IF(OR(S12=D$1,S12=I$1),S12,IF(ABS(Q13-R13)>(20-A13)*8,IF(Q13>R13,D$1,I$1),"TBD")) -> TBD
A14: 11 | B14: =IF(AND(N13<>"",N13>3),B13,1-B13) -> 0 | C14: =IF(B14=0,D$1,I$1) -> Ravens | N14: {=IF(ABS((SUM(E14:H14)+INDEX(E14:H14,1,$D$4))-(SUM(I14:L14)+INDEX(I14:L14,1,$M$4)))>3,(1-2*B14)*((SUM(E14:H14)+INDEX(E14:H14,1,$D$4))-(SUM(I14:L14)+INDEX(I14:L14,1,$M$4))),"")} | O14: {=IF(N14<>"",N14,IF(B14=0,(E14+F14+IF($D$4<=2,INDEX(E14:H14,1,$D$4),0))-(K14+L14+IF($M$4>=3,INDEX(I14:L14,1,$M$4),0)),(I14+J14+IF($M$4<=2,INDEX(I14:L14,1,$M$4),0))-(G14+H14+IF($D$4>=3,INDEX(E14:H14,1,$D$4),0))))} -> 0 | P14: =IF(O14>3,"Onside Kick",IF(O14=3,"TD + 2PC",IF(O14=2,"Touchdown",IF(O14=1,"Field Goal",IF(O14>-2,"Punt",IF(O14=-2,"Safety",IF(O14=-3,"Pick Six","House Call"))))))) -> Punt | Q14: =IF(B14=0,Q13+IF(O14>1,IF(O14=3,8,7),IF(O14=1,3,0)),Q13+IF(O14>-2,0,IF(O14=-2,2,IF(O14=-3,6,7)))) -> 0 | R14: =IF(B14=0,R13+IF(O14>-2,0,IF(O14=-2,2,IF(O14=-3,6,7))),R13+IF(O14>1,IF(O14=3,8,7),IF(O14=1,3,0))) -> 0 | S14: =IF(OR(S13=D$1,S13=I$1),S13,IF(ABS(Q14-R14)>(20-A14)*8,IF(Q14>R14,D$1,I$1),"TBD")) -> TBD
A15: 12 | B15: =IF(AND(N14<>"",N14>3),B14,1-B14) -> 1 | C15: =IF(B15=0,D$1,I$1) -> Steelers | N15: {=IF(ABS((SUM(E15:H15)+INDEX(E15:H15,1,$D$4))-(SUM(I15:L15)+INDEX(I15:L15,1,$M$4)))>3,(1-2*B15)*((SUM(E15:H15)+INDEX(E15:H15,1,$D$4))-(SUM(I15:L15)+INDEX(I15:L15,1,$M$4))),"")} | O15: {=IF(N15<>"",N15,IF(B15=0,(E15+F15+IF($D$4<=2,INDEX(E15:H15,1,$D$4),0))-(K15+L15+IF($M$4>=3,INDEX(I15:L15,1,$M$4),0)),(I15+J15+IF($M$4<=2,INDEX(I15:L15,1,$M$4),0))-(G15+H15+IF($D$4>=3,INDEX(E15:H15,1,$D$4),0))))} -> 0 | P15: =IF(O15>3,"Onside Kick",IF(O15=3,"TD + 2PC",IF(O15=2,"Touchdown",IF(O15=1,"Field Goal",IF(O15>-2,"Punt",IF(O15=-2,"Safety",IF(O15=-3,"Pick Six","House Call"))))))) -> Punt | Q15: =IF(B15=0,Q14+IF(O15>1,IF(O15=3,8,7),IF(O15=1,3,0)),Q14+IF(O15>-2,0,IF(O15=-2,2,IF(O15=-3,6,7)))) -> 0 | R15: =IF(B15=0,R14+IF(O15>-2,0,IF(O15=-2,2,IF(O15=-3,6,7))),R14+IF(O15>1,IF(O15=3,8,7),IF(O15=1,3,0))) -> 0 | S15: =IF(OR(S14=D$1,S14=I$1),S14,IF(ABS(Q15-R15)>(20-A15)*8,IF(Q15>R15,D$1,I$1),"TBD")) -> TBD
A16: 13 | B16: =IF(AND(N15<>"",N15>3),B15,1-B15) -> 0 | C16: =IF(B16=0,D$1,I$1) -> Ravens | N16: {=IF(ABS((SUM(E16:H16)+INDEX(E16:H16,1,$D$4))-(SUM(I16:L16)+INDEX(I16:L16,1,$M$4)))>3,(1-2*B16)*((SUM(E16:H16)+INDEX(E16:H16,1,$D$4))-(SUM(I16:L16)+INDEX(I16:L16,1,$M$4))),"")} | O16: {=IF(N16<>"",N16,IF(B16=0,(E16+F16+IF($D$4<=2,INDEX(E16:H16,1,$D$4),0))-(K16+L16+IF($M$4>=3,INDEX(I16:L16,1,$M$4),0)),(I16+J16+IF($M$4<=2,INDEX(I16:L16,1,$M$4),0))-(G16+H16+IF($D$4>=3,INDEX(E16:H16,1,$D$4),0))))} -> 0 | P16: =IF(O16>3,"Onside Kick",IF(O16=3,"TD + 2PC",IF(O16=2,"Touchdown",IF(O16=1,"Field Goal",IF(O16>-2,"Punt",IF(O16=-2,"Safety",IF(O16=-3,"Pick Six","House Call"))))))) -> Punt | Q16: =IF(B16=0,Q15+IF(O16>1,IF(O16=3,8,7),IF(O16=1,3,0)),Q15+IF(O16>-2,0,IF(O16=-2,2,IF(O16=-3,6,7)))) -> 0 | R16: =IF(B16=0,R15+IF(O16>-2,0,IF(O16=-2,2,IF(O16=-3,6,7))),R15+IF(O16>1,IF(O16=3,8,7),IF(O16=1,3,0))) -> 0 | S16: =IF(OR(S15=D$1,S15=I$1),S15,IF(ABS(Q16-R16)>(20-A16)*8,IF(Q16>R16,D$1,I$1),"TBD")) -> TBD
A17: 14 | B17: =IF(AND(N16<>"",N16>3),B16,1-B16) -> 1 | C17: =IF(B17=0,D$1,I$1) -> Steelers | N17: {=IF(ABS((SUM(E17:H17)+INDEX(E17:H17,1,$D$4))-(SUM(I17:L17)+INDEX(I17:L17,1,$M$4)))>3,(1-2*B17)*((SUM(E17:H17)+INDEX(E17:H17,1,$D$4))-(SUM(I17:L17)+INDEX(I17:L17,1,$M$4))),"")} | O17: {=IF(N17<>"",N17,IF(B17=0,(E17+F17+IF($D$4<=2,INDEX(E17:H17,1,$D$4),0))-(K17+L17+IF($M$4>=3,INDEX(I17:L17,1,$M$4),0)),(I17+J17+IF($M$4<=2,INDEX(I17:L17,1,$M$4),0))-(G17+H17+IF($D$4>=3,INDEX(E17:H17,1,$D$4),0))))} -> 0 | P17: =IF(O17>3,"Onside Kick",IF(O17=3,"TD + 2PC",IF(O17=2,"Touchdown",IF(O17=1,"Field Goal",IF(O17>-2,"Punt",IF(O17=-2,"Safety",IF(O17=-3,"Pick Six","House Call"))))))) -> Punt | Q17: =IF(B17=0,Q16+IF(O17>1,IF(O17=3,8,7),IF(O17=1,3,0)),Q16+IF(O17>-2,0,IF(O17=-2,2,IF(O17=-3,6,7)))) -> 0 | R17: =IF(B17=0,R16+IF(O17>-2,0,IF(O17=-2,2,IF(O17=-3,6,7))),R16+IF(O17>1,IF(O17=3,8,7),IF(O17=1,3,0))) -> 0 | S17: =IF(OR(S16=D$1,S16=I$1),S16,IF(ABS(Q17-R17)>(20-A17)*8,IF(Q17>R17,D$1,I$1),"TBD")) -> TBD
A18: 15 | B18: =IF(AND(N17<>"",N17>3),B17,1-B17) -> 0 | C18: =IF(B18=0,D$1,I$1) -> Ravens | N18: {=IF(ABS((SUM(E18:H18)+INDEX(E18:H18,1,$D$4))-(SUM(I18:L18)+INDEX(I18:L18,1,$M$4)))>3,(1-2*B18)*((SUM(E18:H18)+INDEX(E18:H18,1,$D$4))-(SUM(I18:L18)+INDEX(I18:L18,1,$M$4))),"")} | O18: {=IF(N18<>"",N18,IF(B18=0,(E18+F18+IF($D$4<=2,INDEX(E18:H18,1,$D$4),0))-(K18+L18+IF($M$4>=3,INDEX(I18:L18,1,$M$4),0)),(I18+J18+IF($M$4<=2,INDEX(I18:L18,1,$M$4),0))-(G18+H18+IF($D$4>=3,INDEX(E18:H18,1,$D$4),0))))} -> 0 | P18: =IF(O18>3,"Onside Kick",IF(O18=3,"TD + 2PC",IF(O18=2,"Touchdown",IF(O18=1,"Field Goal",IF(O18>-2,"Punt",IF(O18=-2,"Safety",IF(O18=-3,"Pick Six","House Call"))))))) -> Punt | Q18: =IF(B18=0,Q17+IF(O18>1,IF(O18=3,8,7),IF(O18=1,3,0)),Q17+IF(O18>-2,0,IF(O18=-2,2,IF(O18=-3,6,7)))) -> 0 | R18: =IF(B18=0,R17+IF(O18>-2,0,IF(O18=-2,2,IF(O18=-3,6,7))),R17+IF(O18>1,IF(O18=3,8,7),IF(O18=1,3,0))) -> 0 | S18: =IF(OR(S17=D$1,S17=I$1),S17,IF(ABS(Q18-R18)>(20-A18)*8,IF(Q18>R18,D$1,I$1),"TBD")) -> TBD
A19: 16 | B19: =IF(AND(N18<>"",N18>3),B18,1-B18) -> 1 | C19: =IF(B19=0,D$1,I$1) -> Steelers | N19: {=IF(ABS((SUM(E19:H19)+INDEX(E19:H19,1,$D$4))-(SUM(I19:L19)+INDEX(I19:L19,1,$M$4)))>3,(1-2*B19)*((SUM(E19:H19)+INDEX(E19:H19,1,$D$4))-(SUM(I19:L19)+INDEX(I19:L19,1,$M$4))),"")} | O19: {=IF(N19<>"",N19,IF(B19=0,(E19+F19+IF($D$4<=2,INDEX(E19:H19,1,$D$4),0))-(K19+L19+IF($M$4>=3,INDEX(I19:L19,1,$M$4),0)),(I19+J19+IF($M$4<=2,INDEX(I19:L19,1,$M$4),0))-(G19+H19+IF($D$4>=3,INDEX(E19:H19,1,$D$4),0))))} -> 0 | P19: =IF(O19>3,"Onside Kick",IF(O19=3,"TD + 2PC",IF(O19=2,"Touchdown",IF(O19=1,"Field Goal",IF(O19>-2,"Punt",IF(O19=-2,"Safety",IF(O19=-3,"Pick Six","House Call"))))))) -> Punt | Q19: =IF(B19=0,Q18+IF(O19>1,IF(O19=3,8,7),IF(O19=1,3,0)),Q18+IF(O19>-2,0,IF(O19=-2,2,IF(O19=-3,6,7)))) -> 0 | R19: =IF(B19=0,R18+IF(O19>-2,0,IF(O19=-2,2,IF(O19=-3,6,7))),R18+IF(O19>1,IF(O19=3,8,7),IF(O19=1,3,0))) -> 0 | S19: =IF(OR(S18=D$1,S18=I$1),S18,IF(ABS(Q19-R19)>(20-A19)*8,IF(Q19>R19,D$1,I$1),"TBD")) -> TBD
A20: 17 | B20: =IF(AND(N19<>"",N19>3),B19,1-B19) -> 0 | C20: =IF(B20=0,D$1,I$1) -> Ravens | N20: {=IF(ABS((SUM(E20:H20)+INDEX(E20:H20,1,$D$4))-(SUM(I20:L20)+INDEX(I20:L20,1,$M$4)))>3,(1-2*B20)*((SUM(E20:H20)+INDEX(E20:H20,1,$D$4))-(SUM(I20:L20)+INDEX(I20:L20,1,$M$4))),"")} | O20: {=IF(N20<>"",N20,IF(B20=0,(E20+F20+IF($D$4<=2,INDEX(E20:H20,1,$D$4),0))-(K20+L20+IF($M$4>=3,INDEX(I20:L20,1,$M$4),0)),(I20+J20+IF($M$4<=2,INDEX(I20:L20,1,$M$4),0))-(G20+H20+IF($D$4>=3,INDEX(E20:H20,1,$D$4),0))))} -> 0 | P20: =IF(O20>3,"Onside Kick",IF(O20=3,"TD + 2PC",IF(O20=2,"Touchdown",IF(O20=1,"Field Goal",IF(O20>-2,"Punt",IF(O20=-2,"Safety",IF(O20=-3,"Pick Six","House Call"))))))) -> Punt | Q20: =IF(B20=0,Q19+IF(O20>1,IF(O20=3,8,7),IF(O20=1,3,0)),Q19+IF(O20>-2,0,IF(O20=-2,2,IF(O20=-3,6,7)))) -> 0 | R20: =IF(B20=0,R19+IF(O20>-2,0,IF(O20=-2,2,IF(O20=-3,6,7))),R19+IF(O20>1,IF(O20=3,8,7),IF(O20=1,3,0))) -> 0 | S20: =IF(OR(S19=D$1,S19=I$1),S19,IF(ABS(Q20-R20)>(20-A20)*8,IF(Q20>R20,D$1,I$1),"TBD")) -> TBD
A21: 18 | B21: =IF(AND(N20<>"",N20>3),B20,1-B20) -> 1 | C21: =IF(B21=0,D$1,I$1) -> Steelers | N21: {=IF(ABS((SUM(E21:H21)+INDEX(E21:H21,1,$D$4))-(SUM(I21:L21)+INDEX(I21:L21,1,$M$4)))>3,(1-2*B21)*((SUM(E21:H21)+INDEX(E21:H21,1,$D$4))-(SUM(I21:L21)+INDEX(I21:L21,1,$M$4))),"")} | O21: {=IF(N21<>"",N21,IF(B21=0,(E21+F21+IF($D$4<=2,INDEX(E21:H21,1,$D$4),0))-(K21+L21+IF($M$4>=3,INDEX(I21:L21,1,$M$4),0)),(I21+J21+IF($M$4<=2,INDEX(I21:L21,1,$M$4),0))-(G21+H21+IF($D$4>=3,INDEX(E21:H21,1,$D$4),0))))} -> 0 | P21: =IF(O21>3,"Onside Kick",IF(O21=3,"TD + 2PC",IF(O21=2,"Touchdown",IF(O21=1,"Field Goal",IF(O21>-2,"Punt",IF(O21=-2,"Safety",IF(O21=-3,"Pick Six","House Call"))))))) -> Punt | Q21: =IF(B21=0,Q20+IF(O21>1,IF(O21=3,8,7),IF(O21=1,3,0)),Q20+IF(O21>-2,0,IF(O21=-2,2,IF(O21=-3,6,7)))) -> 0 | R21: =IF(B21=0,R20+IF(O21>-2,0,IF(O21=-2,2,IF(O21=-3,6,7))),R20+IF(O21>1,IF(O21=3,8,7),IF(O21=1,3,0))) -> 0 | S21: =IF(OR(S20=D$1,S20=I$1),S20,IF(ABS(Q21-R21)>(20-A21)*8,IF(Q21>R21,D$1,I$1),"TBD")) -> TBD
A22: 19 | B22: =IF(AND(N21<>"",N21>3),B21,1-B21) -> 0 | C22: =IF(B22=0,D$1,I$1) -> Ravens | N22: {=IF(ABS((SUM(E22:H22)+INDEX(E22:H22,1,$D$4))-(SUM(I22:L22)+INDEX(I22:L22,1,$M$4)))>3,(1-2*B22)*((SUM(E22:H22)+INDEX(E22:H22,1,$D$4))-(SUM(I22:L22)+INDEX(I22:L22,1,$M$4))),"")} | O22: {=IF(N22<>"",N22,IF(B22=0,(E22+F22+IF($D$4<=2,INDEX(E22:H22,1,$D$4),0))-(K22+L22+IF($M$4>=3,INDEX(I22:L22,1,$M$4),0)),(I22+J22+IF($M$4<=2,INDEX(I22:L22,1,$M$4),0))-(G22+H22+IF($D$4>=3,INDEX(E22:H22,1,$D$4),0))))} -> 0 | P22: =IF(O22>3,"Onside Kick",IF(O22=3,"TD + 2PC",IF(O22=2,"Touchdown",IF(O22=1,"Field Goal",IF(O22>-2,"Punt",IF(O22=-2,"Safety",IF(O22=-3,"Pick Six","House Call"))))))) -> Punt | Q22: =IF(B22=0,Q21+IF(O22>1,IF(O22=3,8,7),IF(O22=1,3,0)),Q21+IF(O22>-2,0,IF(O22=-2,2,IF(O22=-3,6,7)))) -> 0 | R22: =IF(B22=0,R21+IF(O22>-2,0,IF(O22=-2,2,IF(O22=-3,6,7))),R21+IF(O22>1,IF(O22=3,8,7),IF(O22=1,3,0))) -> 0 | S22: =IF(OR(S21=D$1,S21=I$1),S21,IF(ABS(Q22-R22)>(20-A22)*8,IF(Q22>R22,D$1,I$1),"TBD")) -> TBD
A23: 20 | B23: =IF(AND(N22<>"",N22>3),B22,1-B22) -> 1 | C23: =IF(B23=0,D$1,I$1) -> Steelers | N23: {=IF(ABS((SUM(E23:H23)+INDEX(E23:H23,1,$D$4))-(SUM(I23:L23)+INDEX(I23:L23,1,$M$4)))>3,(1-2*B23)*((SUM(E23:H23)+INDEX(E23:H23,1,$D$4))-(SUM(I23:L23)+INDEX(I23:L23,1,$M$4))),"")} | O23: {=IF(N23<>"",N23,IF(B23=0,(E23+F23+IF($D$4<=2,INDEX(E23:H23,1,$D$4),0))-(K23+L23+IF($M$4>=3,INDEX(I23:L23,1,$M$4),0)),(I23+J23+IF($M$4<=2,INDEX(I23:L23,1,$M$4),0))-(G23+H23+IF($D$4>=3,INDEX(E23:H23,1,$D$4),0))))} -> 0 | P23: =IF(O23>3,"Onside Kick",IF(O23=3,"TD + 2PC",IF(O23=2,"Touchdown",IF(O23=1,"Field Goal",IF(O23>-2,"Punt",IF(O23=-2,"Safety",IF(O23=-3,"Pick Six","House Call"))))))) -> Punt | Q23: =IF(B23=0,Q22+IF(O23>1,IF(O23=3,8,7),IF(O23=1,3,0)),Q22+IF(O23>-2,0,IF(O23=-2,2,IF(O23=-3,6,7)))) -> 0 | R23: =IF(B23=0,R22+IF(O23>-2,0,IF(O23=-2,2,IF(O23=-3,6,7))),R22+IF(O23>1,IF(O23=3,8,7),IF(O23=1,3,0))) -> 0 | S23: =IF(OR(S22=D$1,S22=I$1),S22,IF(ABS(Q23-R23)>(20-A23)*8,IF(Q23>R23,D$1,I$1),"TBD")) -> TBD
A24: Overtime: 5 Random Songs. Onside/Safety/Pick ends it on Song 1, Sudden Death from Song 2
A25: 1 | B25: 0 | C25: =IF(B25=0,D$1,I$1) -> Ravens | D25: =D4 -> 1 | M25: =M4 -> 1 | N25: {=IF(ABS((SUM(E25:H25)+INDEX(E25:H25,1,$D$4))-(SUM(I25:L25)+INDEX(I25:L25,1,$M$4)))>3,(1-2*B25)*((SUM(E25:H25)+INDEX(E25:H25,1,$D$4))-(SUM(I25:L25)+INDEX(I25:L25,1,$M$4))),"")} | O25: {=IF(N25<>"",N25,IF(B25=0,(E25+F25+IF($D$4<=2,INDEX(E25:H25,1,$D$4),0))-(K25+L25+IF($M$4>=3,INDEX(I25:L25,1,$M$4),0)),(I25+J25+IF($M$4<=2,INDEX(I25:L25,1,$M$4),0))-(G25+H25+IF($D$4>=3,INDEX(E25:H25,1,$D$4),0))))} -> 0 | P25: =IF(O25>3,"Onside Kick",IF(O25=3,"TD + 2PC",IF(O25=2,"Touchdown",IF(O25=1,"Field Goal",IF(O25>-2,"Punt",IF(O25=-2,"Safety",IF(O25=-3,"Pick Six","House Call"))))))) -> Punt | Q25: =Q23+IF(O25>2,IF(O25=3,8,7),IF(O25=2,6,IF(O25=1,3,0))) -> 0 | R25: =R23+IF(O25>-2,0,IF(O25=-2,2,IF(O25=-3,6,7))) -> 0 | S25: =IF(OR(S23=D$1,S23=I$1),S23,IF(A25=1,IF(O25>3,$D$1,IF(O25<-1,$I$1,"TBD")),IF(Q25>R25,$D$1,IF(R25>Q25,$I$1,IF(A25=5,"Tie","TBD"))))) -> TBD
A26: 2 | B26: =IF(AND(N25<>"",N25>3),B25,1-B25) -> 1 | C26: =IF(B26=0,D$1,I$1) -> Steelers | N26: {=IF(ABS((SUM(E26:H26)+INDEX(E26:H26,1,$D$4))-(SUM(I26:L26)+INDEX(I26:L26,1,$M$4)))>3,(1-2*B26)*((SUM(E26:H26)+INDEX(E26:H26,1,$D$4))-(SUM(I26:L26)+INDEX(I26:L26,1,$M$4))),"")} | O26: {=IF(N26<>"",N26,IF(B26=0,(E26+F26+IF($D$4<=2,INDEX(E26:H26,1,$D$4),0))-(K26+L26+IF($M$4>=3,INDEX(I26:L26,1,$M$4),0)),(I26+J26+IF($M$4<=2,INDEX(I26:L26,1,$M$4),0))-(G26+H26+IF($D$4>=3,INDEX(E26:H26,1,$D$4),0))))} -> 0 | P26: =IF(O26>3,"Onside Kick",IF(O26=3,"TD + 2PC",IF(O26=2,"Touchdown",IF(O26=1,"Field Goal",IF(O26>-2,"Punt",IF(O26=-2,"Safety",IF(O26=-3,"Pick Six","House Call"))))))) -> Punt | Q26: =IF(B26=0,Q25+IF(O26>1,IF(O26=3,8,7),IF(O26=1,3,0)),Q25+IF(O26>-2,0,IF(O26=-2,2,IF(O26=-3,6,7)))) -> 0 | R26: =IF(B26=0,R25+IF(O26>-2,0,IF(O26=-2,2,IF(O26=-3,6,7))),R25+IF(O26>1,IF(O26=3,8,7),IF(O26=1,3,0))) -> 0 | S26: =IF(OR(S25=D$1,S25=I$1),S25,IF(A26=1,IF(O26>3,$D$1,IF(O26<-1,$I$1,"TBD")),IF(Q26>R26,$D$1,IF(R26>Q26,$I$1,IF(A26=5,"Tie","TBD"))))) -> TBD
A27: 3 | B27: =IF(AND(N26<>"",N26>3),B26,1-B26) -> 0 | C27: =IF(B27=0,D$1,I$1) -> Ravens | N27: {=IF(ABS((SUM(E27:H27)+INDEX(E27:H27,1,$D$4))-(SUM(I27:L27)+INDEX(I27:L27,1,$M$4)))>3,(1-2*B27)*((SUM(E27:H27)+INDEX(E27:H27,1,$D$4))-(SUM(I27:L27)+INDEX(I27:L27,1,$M$4))),"")} | O27: {=IF(N27<>"",N27,IF(B27=0,(E27+F27+IF($D$4<=2,INDEX(E27:H27,1,$D$4),0))-(K27+L27+IF($M$4>=3,INDEX(I27:L27,1,$M$4),0)),(I27+J27+IF($M$4<=2,INDEX(I27:L27,1,$M$4),0))-(G27+H27+IF($D$4>=3,INDEX(E27:H27,1,$D$4),0))))} -> 0 | P27: =IF(O27>3,"Onside Kick",IF(O27=3,"TD + 2PC",IF(O27=2,"Touchdown",IF(O27=1,"Field Goal",IF(O27>-2,"Punt",IF(O27=-2,"Safety",IF(O27=-3,"Pick Six","House Call"))))))) -> Punt | Q27: =IF(B27=0,Q26+IF(O27>1,IF(O27=3,8,7),IF(O27=1,3,0)),Q26+IF(O27>-2,0,IF(O27=-2,2,IF(O27=-3,6,7)))) -> 0 | R27: =IF(B27=0,R26+IF(O27>-2,0,IF(O27=-2,2,IF(O27=-3,6,7))),R26+IF(O27>1,IF(O27=3,8,7),IF(O27=1,3,0))) -> 0 | S27: =IF(OR(S26=D$1,S26=I$1),S26,IF(A27=1,IF(O27>3,$D$1,IF(O27<-1,$I$1,"TBD")),IF(Q27>R27,$D$1,IF(R27>Q27,$I$1,IF(A27=5,"Tie","TBD"))))) -> TBD
A28: 4 | B28: =IF(AND(N27<>"",N27>3),B27,1-B27) -> 1 | C28: =IF(B28=0,D$1,I$1) -> Steelers | N28: {=IF(ABS((SUM(E28:H28)+INDEX(E28:H28,1,$D$4))-(SUM(I28:L28)+INDEX(I28:L28,1,$M$4)))>3,(1-2*B28)*((SUM(E28:H28)+INDEX(E28:H28,1,$D$4))-(SUM(I28:L28)+INDEX(I28:L28,1,$M$4))),"")} | O28: {=IF(N28<>"",N28,IF(B28=0,(E28+F28+IF($D$4<=2,INDEX(E28:H28,1,$D$4),0))-(K28+L28+IF($M$4>=3,INDEX(I28:L28,1,$M$4),0)),(I28+J28+IF($M$4<=2,INDEX(I28:L28,1,$M$4),0))-(G28+H28+IF($D$4>=3,INDEX(E28:H28,1,$D$4),0))))} -> 0 | P28: =IF(O28>3,"Onside Kick",IF(O28=3,"TD + 2PC",IF(O28=2,"Touchdown",IF(O28=1,"Field Goal",IF(O28>-2,"Punt",IF(O28=-2,"Safety",IF(O28=-3,"Pick Six","House Call"))))))) -> Punt | Q28: =IF(B28=0,Q27+IF(O28>1,IF(O28=3,8,7),IF(O28=1,3,0)),Q27+IF(O28>-2,0,IF(O28=-2,2,IF(O28=-3,6,7)))) -> 0 | R28: =IF(B28=0,R27+IF(O28>-2,0,IF(O28=-2,2,IF(O28=-3,6,7))),R27+IF(O28>1,IF(O28=3,8,7),IF(O28=1,3,0))) -> 0 | S28: =IF(OR(S27=D$1,S27=I$1),S27,IF(A28=1,IF(O28>3,$D$1,IF(O28<-1,$I$1,"TBD")),IF(Q28>R28,$D$1,IF(R28>Q28,$I$1,IF(A28=5,"Tie","TBD"))))) -> TBD
A29: 5 | B29: =IF(AND(N28<>"",N28>3),B28,1-B28) -> 0 | C29: =IF(B29=0,D$1,I$1) -> Ravens | N29: {=IF(ABS((SUM(E29:H29)+INDEX(E29:H29,1,$D$4))-(SUM(I29:L29)+INDEX(I29:L29,1,$M$4)))>3,(1-2*B29)*((SUM(E29:H29)+INDEX(E29:H29,1,$D$4))-(SUM(I29:L29)+INDEX(I29:L29,1,$M$4))),"")} | O29: {=IF(N29<>"",N29,IF(B29=0,(E29+F29+IF($D$4<=2,INDEX(E29:H29,1,$D$4),0))-(K29+L29+IF($M$4>=3,INDEX(I29:L29,1,$M$4),0)),(I29+J29+IF($M$4<=2,INDEX(I29:L29,1,$M$4),0))-(G29+H29+IF($D$4>=3,INDEX(E29:H29,1,$D$4),0))))} -> 0 | P29: =IF(O29>3,"Onside Kick",IF(O29=3,"TD + 2PC",IF(O29=2,"Touchdown",IF(O29=1,"Field Goal",IF(O29>-2,"Punt",IF(O29=-2,"Safety",IF(O29=-3,"Pick Six","House Call"))))))) -> Punt | Q29: =IF(B29=0,Q28+IF(O29>1,IF(O29=3,8,7),IF(O29=1,3,0)),Q28+IF(O29>-2,0,IF(O29=-2,2,IF(O29=-3,6,7)))) -> 0 | R29: =IF(B29=0,R28+IF(O29>-2,0,IF(O29=-2,2,IF(O29=-3,6,7))),R28+IF(O29>1,IF(O29=3,8,7),IF(O29=1,3,0))) -> 0 | S29: =IF(OR(S28=D$1,S28=I$1),S28,IF(A29=1,IF(O29>3,$D$1,IF(O29<-1,$I$1,"TBD")),IF(Q29>R29,$D$1,IF(R29>Q29,$I$1,IF(A29=5,"Tie","TBD"))))) -> Tie

Sheet Game 2
A1: Song | B1: Poss. | C1: Poss. | D1: Ravens | I1: Steelers | N1: TDIFF | O1: DIFF | P1: Result | Q1: Score | S1: Winner
D2: C | E2: OP1 | F2: OP2 | G2: DP1 | H2: DP2 | I2: OP1 | J2: OP2 | K2: DP1 | L2: DP2 | M2: C | Q2: =D1 -> Ravens | R2: =I1 -> Steelers | U2: 1 | V2: Change E1 and I1 to the right Away and Home teams
A3: Regulation: 16 Watched Equal, 4 Random songs. Mercy Rule if Score Deficit > Remaining Songs × 8 | U3: 2 | V3: Fill Column E to L with 1 for whoever gets each song right
A4: 1 | B4: 0 | C4: =IF(B4=0,D$1,I$1) -> Ravens | D4: {=_xlfn.SWITCH(VLOOKUP(D1,Setup!A:C,3,FALSE),"OP1",1,"OP2",2,"DP1",3,"DP2",4,1)} -> 1 | M4: {=_xlfn.SWITCH(VLOOKUP(I1,Setup!A:C,3,FALSE),"OP1",1,"OP2",2,"DP1",3,"DP2",4,1)} -> 1 | N4: {=IF(ABS((SUM(E4:H4)+INDEX(E4:H4,1,$D$4))-(SUM(I4:L4)+INDEX(I4:L4,1,$M$4)))>3,(1-2*B4)*((SUM(E4:H4)+INDEX(E4:H4,1,$D$4))-(SUM(I4:L4)+INDEX(I4:L4,1,$M$4))),"")} | O4: {=IF(N4<>"",N4,IF(B4=0,(E4+F4+IF($D$4<=2,INDEX(E4:H4,1,$D$4),0))-(K4+L4+IF($M$4>=3,INDEX(I4:L4,1,$M$4),0)),(I4+J4+IF($M$4<=2,INDEX(I4:L4,1,$M$4),0))-(G4+H4+IF($D$4>=3,INDEX(E4:H4,1,$D$4),0))))} -> 0 | P4: =IF(O4>3,"Onside Kick",IF(O4=3,"TD + 2PC",IF(O4=2,"Touchdown",IF(O4=1,"Field Goal",IF(O4>-2,"Punt",IF(O4=-2,"Safety",IF(O4=-3,"Pick Six","House Call"))))))) -> Punt | Q4: =IF(O4>1,IF(O4=3,8,7),IF(O4=1,3,0)) -> 0 | R4: =IF(O4>-2,0,IF(O4=-2,2,IF(O4=-3,6,7))) -> 0 | S4: =IF(OR(S3=D$1,S3=I$1),S3,IF(ABS(Q4-R4)>(20-A4)*8,IF(Q4>R4,D$1,I$1),"TBD")) -> TBD | U4: 3 | V4: Continue playing until either happens:
A5: 2 | B5: =IF(AND(N4<>"",N4>3),B4,1-B4) -> 1 | C5: =IF(B5=0,D$1,I$1) -> Steelers | N5: {=IF(ABS((SUM(E5:H5)+INDEX(E5:H5,1,$D$4))-(SUM(I5:L5)+INDEX(I5:L5,1,$M$4)))>3,(1-2*B5)*((SUM(E5:H5)+INDEX(E5:H5,1,$D$4))-(SUM(I5:L5)+INDEX(I5:L5,1,$M$4))),"")} | O5: {=IF(N5<>"",N5,IF(B5=0,(E5+F5+IF($D$4<=2,INDEX(E5:H5,1,$D$4),0))-(K5+L5+IF($M$4>=3,INDEX(I5:L5,1,$M$4),0)),(I5+J5+IF($M$4<=2,INDEX(I5:L5,1,$M$4),0))-(G5+H5+IF($D$4>=3,INDEX(E5:H5,1,$D$4),0))))} -> 0 | P5: =IF(O5>3,"Onside Kick",IF(O5=3,"TD + 2PC",IF(O5=2,"Touchdown",IF(O5=1,"Field Goal",IF(O5>-2,"Punt",IF(O5=-2,"Safety",IF(O5=-3,"Pick Six","House Call"))))))) -> Punt | Q5: =IF(B5=0,Q4+IF(O5>1,IF(O5=3,8,7),IF(O5=1,3,0)),Q4+IF(O5>-2,0,IF(O5=-2,2,IF(O5=-3,6,7)))) -> 0 | R5: =IF(B5=0,R4+IF(O5>-2,0,IF(O5=-2,2,IF(O5=-3,6,7))),R4+IF(O5>1,IF(O5=3,8,7),IF(O5=1,3,0))) -> 0 | S5: =IF(OR(S4=D$1,S4=I$1),S4,IF(ABS(Q5-R5)>(20-A5)*8,IF(Q5>R5,D$1,I$1),"TBD")) -> TBD | V5: 1 | W5: You run out of songs, or
A6: 3 | B6: =IF(AND(N5<>"",N5>3),B5,1-B5) -> 0 | C6: =IF(B6=0,D$1,I$1) -> Ravens | N6: {=IF(ABS((SUM(E6:H6)+INDEX(E6:H6,1,$D$4))-(SUM(I6:L6)+INDEX(I6:L6,1,$M$4)))>3,(1-2*B6)*((SUM(E6:H6)+INDEX(E6:H6,1,$D$4))-(SUM(I6:L6)+INDEX(I6:L6,1,$M$4))),"")} | O6: {=IF(N6<>"",N6,IF(B6=0,(E6+F6+IF($D$4<=2,INDEX(E6:H6,1,$D$4),0))-(K6+L6+IF($M$4>=3,INDEX(I6:L6,1,$M$4),0)),(I6+J6+IF($M$4<=2,INDEX(I6:L6,1,$M$4),0))-(G6+H6+IF($D$4>=3,INDEX(E6:H6,1,$D$4),0))))} -> 0 | P6: =IF(O6>3,"Onside Kick",IF(O6=3,"TD + 2PC",IF(O6=2,"Touchdown",IF(O6=1,"Field Goal",IF(O6>-2,"Punt",IF(O6=-2,"Safety",IF(O6=-3,"Pick Six","House Call"))))))) -> Punt | Q6: =IF(B6=0,Q5+IF(O6>1,IF(O6=3,8,7),IF(O6=1,3,0)),Q5+IF(O6>-2,0,IF(O6=-2,2,IF(O6=-3,6,7)))) -> 0 | R6: =IF(B6=0,R5+IF(O6>-2,0,IF(O6=-2,2,IF(O6=-3,6,7))),R5+IF(O6>1,IF(O6=3,8,7),IF(O6=1,3,0))) -> 0 | S6: =IF(OR(S5=D$1,S5=I$1),S5,IF(ABS(Q6-R6)>(20-A6)*8,IF(Q6>R6,D$1,I$1),"TBD")) -> TBD | V6: 2 | W6: Winner column on current Song row is not TBD
A7: 4 | B7: =IF(AND(N6<>"",N6>3),B6,1-B6) -> 1 | C7: =IF(B7=0,D$1,I$1) -> Steelers | N7: {=IF(ABS((SUM(E7:H7)+INDEX(E7:H7,1,$D$4))-(SUM(I7:L7)+INDEX(I7:L7,1,$M$4)))>3,(1-2*B7)*((SUM(E7:H7)+INDEX(E7:H7,1,$D$4))-(SUM(I7:L7)+INDEX(I7:L7,1,$M$4))),"")} | O7: {=IF(N7<>"",N7,IF(B7=0,(E7+F7+IF($D$4<=2,INDEX(E7:H7,1,$D$4),0))-(K7+L7+IF($M$4>=3,INDEX(I7:L7,1,$M$4),0)),(I7+J7+IF($M$4<=2,INDEX(I7:L7,1,$M$4),0))-(G7+H7+IF($D$4>=3,INDEX(E7:H7,1,$D$4),0))))} -> 0 | P7: =IF(O7>3,"Onside Kick",IF(O7=3,"TD + 2PC",IF(O7=2,"Touchdown",IF(O7=1,"Field Goal",IF(O7>-2,"Punt",IF(O7=-2,"Safety",IF(O7=-3,"Pick Six","House Call"))))))) -> Punt | Q7: =IF(B7=0,Q6+IF(O7>1,IF(O7=3,8,7),IF(O7=1,3,0)),Q6+IF(O7>-2,0,IF(O7=-2,2,IF(O7=-3,6,7)))) -> 0 | R7: =IF(B7=0,R6+IF(O7>-2,0,IF(O7=-2,2,IF(O7=-3,6,7))),R6+IF(O7>1,IF(O7=3,8,7),IF(O7=1,3,0))) -> 0 | S7: =IF(OR(S6=D$1,S6=I$1),S6,IF(ABS(Q7-R7)>(20-A7)*8,IF(Q7>R7,D$1,I$1),"TBD")) -> TBD | U7: 4 | V7: Continue to the next Game scoresheet
A8: 5 | B8: =IF(AND(N7<>"",N7>3),B7,1-B7) -> 0 | C8: =IF(B8=0,D$1,I$1) -> Ravens | N8: {=IF(ABS((SUM(E8:H8)+INDEX(E8:H8,1,$D$4))-(SUM(I8:L8)+INDEX(I8:L8,1,$M$4)))>3,(1-2*B8)*((SUM(E8:H8)+INDEX(E8:H8,1,$D$4))-(SUM(I8:L8)+INDEX(I8:L8,1,$M$4))),"")} | O8: {=IF(N8<>"",N8,IF(B8=0,(E8+F8+IF($D$4<=2,INDEX(E8:H8,1,$D$4),0))-(K8+L8+IF($M$4>=3,INDEX(I8:L8,1,$M$4),0)),(I8+J8+IF($M$4<=2,INDEX(I8:L8,1,$M$4),0))-(G8+H8+IF($D$4>=3,INDEX(E8:H8,1,$D$4),0))))} -> 0 | P8: =IF(O8>3,"Onside Kick",IF(O8=3,"TD + 2PC",IF(O8=2,"Touchdown",IF(O8=1,"Field Goal",IF(O8>-2,"Punt",IF(O8=-2,"Safety",IF(O8=-3,"Pick Six","House Call"))))))) -> Punt | Q8: =IF(B8=0,Q7+IF(O8>1,IF(O8=3,8,7),IF(O8=1,3,0)),Q7+IF(O8>-2,0,IF(O8=-2,2,IF(O8=-3,6,7)))) -> 0 | R8: =IF(B8=0,R7+IF(O8>-2,0,IF(O8=-2,2,IF(O8=-3,6,7))),R7+IF(O8>1,IF(O8=3,8,7),IF(O8=1,3,0))) -> 0 | S8: =IF(OR(S7=D$1,S7=I$1),S7,IF(ABS(Q8-R8)>(20-A8)*8,IF(Q8>R8,D$1,I$1),"TBD")) -> TBD | V8: Swap Away and Home if you play the same team again
A9: 6 | B9: =IF(AND(N8<>"",N8>3),B8,1-B8) -> 1 | C9: =IF(B9=0,D$1,I$1) -> Steelers | N9: {=IF(ABS((SUM(E9:H9)+INDEX(E9:H9,1,$D$4))-(SUM(I9:L9)+INDEX(I9:L9,1,$M$4)))>3,(1-2*B9)*((SUM(E9:H9)+INDEX(E9:H9,1,$D$4))-(SUM(I9:L9)+INDEX(I9:L9,1,$M$4))),"")} | O9: {=IF(N9<>"",N9,IF(B9=0,(E9+F9+IF($D$4<=2,INDEX(E9:H9,1,$D$4),0))-(K9+L9+IF($M$4>=3,INDEX(I9:L9,1,$M$4),0)),(I9+J9+IF($M$4<=2,INDEX(I9:L9,1,$M$4),0))-(G9+H9+IF($D$4>=3,INDEX(E9:H9,1,$D$4),0))))} -> 0 | P9: =IF(O9>3,"Onside Kick",IF(O9=3,"TD + 2PC",IF(O9=2,"Touchdown",IF(O9=1,"Field Goal",IF(O9>-2,"Punt",IF(O9=-2,"Safety",IF(O9=-3,"Pick Six","House Call"))))))) -> Punt | Q9: =IF(B9=0,Q8+IF(O9>1,IF(O9=3,8,7),IF(O9=1,3,0)),Q8+IF(O9>-2,0,IF(O9=-2,2,IF(O9=-3,6,7)))) -> 0 | R9: =IF(B9=0,R8+IF(O9>-2,0,IF(O9=-2,2,IF(O9=-3,6,7))),R8+IF(O9>1,IF(O9=3,8,7),IF(O9=1,3,0))) -> 0 | S9: =IF(OR(S8=D$1,S8=I$1),S8,IF(ABS(Q9-R9)>(20-A9)*8,IF(Q9>R9,D$1,I$1),"TBD")) -> TBD | U9: 5 | V9: Report the link to your copy after the last game
A10: 7 | B10: =IF(AND(N9<>"",N9>3),B9,1-B9) -> 0 | C10: =IF(B10=0,D$1,I$1) -> Ravens | N10: {=IF(ABS((SUM(E10:H10)+INDEX(E10:H10,1,$D$4))-(SUM(I10:L10)+INDEX(I10:L10,1,$M$4)))>3,(1-2*B10)*((SUM(E10:H10)+INDEX(E10:H10,1,$D$4))-(SUM(I10:L10)+INDEX(I10:L10,1,$M$4))),"")} | O10: {=IF(N10<>"",N10,IF(B10=0,(E10+F10+IF($D$4<=2,INDEX(E10:H10,1,$D$4),0))-(K10+L10+IF($M$4>=3,INDEX(I10:L10,1,$M$4),0)),(I10+J10+IF($M$4<=2,INDEX(I10:L10,1,$M$4),0))-(G10+H10+IF($D$4>=3,INDEX(E10:H10,1,$D$4),0))))} -> 0 | P10: =IF(O10>3,"Onside Kick",IF(O10=3,"TD + 2PC",IF(O10=2,"Touchdown",IF(O10=1,"Field Goal",IF(O10>-2,"Punt",IF(O10=-2,"Safety",IF(O10=-3,"Pick Six","House Call"))))))) -> Punt | Q10: =IF(B10=0,Q9+IF(O10>1,IF(O10=3,8,7),IF(O10=1,3,0)),Q9+IF(O10>-2,0,IF(O10=-2,2,IF(O10=-3,6,7)))) -> 0 | R10: =IF(B10=0,R9+IF(O10>-2,0,IF(O10=-2,2,IF(O10=-3,6,7))),R9+IF(O10>1,IF(O10=3,8,7),IF(O10=1,3,0))) -> 0 | S10: =IF(OR(S9=D$1,S9=I$1),S9,IF(ABS(Q10-R10)>(20-A10)*8,IF(Q10>R10,D$1,I$1),"TBD")) -> TBD | U10: If you get a Protection Error, you probably shouldn't touch that cell
A11: 8 | B11: =IF(AND(N10<>"",N10>3),B10,1-B10) -> 1 | C11: =IF(B11=0,D$1,I$1) -> Steelers | N11: {=IF(ABS((SUM(E11:H11)+INDEX(E11:H11,1,$D$4))-(SUM(I11:L11)+INDEX(I11:L11,1,$M$4)))>3,(1-2*B11)*((SUM(E11:H11)+INDEX(E11:H11,1,$D$4))-(SUM(I11:L11)+INDEX(I11:L11,1,$M$4))),"")} | O11: {=IF(N11<>"",N11,IF(B11=0,(E11+F11+IF($D$4<=2,INDEX(E11:H11,1,$D$4),0))-(K11+L11+IF($M$4>=3,INDEX(I11:L11,1,$M$4),0)),(I11+J11+IF($M$4<=2,INDEX(I11:L11,1,$M$4),0))-(G11+H11+IF($D$4>=3,INDEX(E11:H11,1,$D$4),0))))} -> 0 | P11: =IF(O11>3,"Onside Kick",IF(O11=3,"TD + 2PC",IF(O11=2,"Touchdown",IF(O11=1,"Field Goal",IF(O11>-2,"Punt",IF(O11=-2,"Safety",IF(O11=-3,"Pick Six","House Call"))))))) -> Punt | Q11: =IF(B11=0,Q10+IF(O11>1,IF(O11=3,8,7),IF(O11=1,3,0)),Q10+IF(O11>-2,0,IF(O11=-2,2,IF(O11=-3,6,7)))) -> 0 | R11: =IF(B11=0,R10+IF(O11>-2,0,IF(O11=-2,2,IF(O11=-3,6,7))),R10+IF(O11>1,IF(O11=3,8,7),IF(O11=1,3,0))) -> 0 | S11: =IF(OR(S10=D$1,S10=I$1),S10,IF(ABS(Q11-R11)>(20-A11)*8,IF(Q11>R11,D$1,I$1),"TBD")) -> TBD | U11: If you must unprotect this sheet/workbook, the password is AMQ
A12: 9 | B12: =IF(AND(N11<>"",N11>3),B11,1-B11) -> 0 | C12: =IF(B12=0,D$1,I$1) -> Ravens | N12: {=IF(ABS((SUM(E12:H12)+INDEX(E12:H12,1,$D$4))-(SUM(I12:L12)+INDEX(I12:L12,1,$M$4)))>3,(1-2*B12)*((SUM(E12:H12)+INDEX(E12:H12,1,$D$4))-(SUM(I12:L12)+INDEX(I12:L12,1,$M$4))),"")} | O12: {=IF(N12<>"",N12,IF(B12=0,(E12+F12+IF($D$4<=2,INDEX(E12:H12,1,$D$4),0))-(K12+L12+IF($M$4>=3,INDEX(I12:L12,1,$M$4),0)),(I12+J12+IF($M$4<=2,INDEX(I12:L12,1,$M$4),0))-(G12+H12+IF($D$4>=3,INDEX(E12:H12,1,$D$4),0))))} -> 0 | P12: =IF(O12>3,"Onside Kick",IF(O12=3,"TD + 2PC",IF(O12=2,"Touchdown",IF(O12=1,"Field Goal",IF(O12>-2,"Punt",IF(O12=-2,"Safety",IF(O12=-3,"Pick Six","House Call"))))))) -> Punt | Q12: =IF(B12=0,Q11+IF(O12>1,IF(O12=3,8,7),IF(O12=1,3,0)),Q11+IF(O12>-2,0,IF(O12=-2,2,IF(O12=-3,6,7)))) -> 0 | R12: =IF(B12=0,R11+IF(O12>-2,0,IF(O12=-2,2,IF(O12=-3,6,7))),R11+IF(O12>1,IF(O12=3,8,7),IF(O12=1,3,0))) -> 0 | S12: =IF(OR(S11=D$1,S11=I$1),S11,IF(ABS(Q12-R12)>(20-A12)*8,IF(Q12>R12,D$1,I$1),"TBD")) -> TBD
A13: 10 | B13: =IF(AND(N12<>"",N12>3),B12,1-B12) -> 1 | C13: =IF(B13=0,D$1,I$1) -> Steelers | N13: {=IF(ABS((SUM(E13:H13)+INDEX(E13:H13,1,$D$4))-(SUM(I13:L13)+INDEX(I13:L13,1,$M$4)))>3,(1-2*B13)*((SUM(E13:H13)+INDEX(E13:H13,1,$D$4))-(SUM(I13:L13)+INDEX(I13:L13,1,$M$4))),"")} | O13: {=IF(N13<>"",N13,IF(B13=0,(E13+F13+IF($D$4<=2,INDEX(E13:H13,1,$D$4),0))-(K13+L13+IF($M$4>=3,INDEX(I13:L13,1,$M$4),0)),(I13+J13+IF($M$4<=2,INDEX(I13:L13,1,$M$4),0))-(G13+H13+IF($D$4>=3,INDEX(E13:H13,1,$D$4),0))))} -> 0 | P13: =IF(O13>3,"Onside Kick",IF(O13=3,"TD + 2PC",IF(O13=2,"Touchdown",IF(O13=1,"Field Goal",IF(O13>-2,"Punt",IF(O13=-2,"Safety",IF(O13=-3,"Pick Six","House Call"))))))) -> Punt | Q13: =IF(B13=0,Q12+IF(O13>1,IF(O13=3,8,7),IF(O13=1,3,0)),Q12+IF(O13>-2,0,IF(O13=-2,2,IF(O13=-3,6,7)))) -> 0 | R13: =IF(B13=0,R12+IF(O13>-2,0,IF(O13=-2,2,IF(O13=-3,6,7))),R12+IF(O13>1,IF(O13=3,8,7),IF(O13=1,3,0))) -> 0 | S13: =IF(OR(S12=D$1,S12=I$1),S12,IF(ABS(Q13-R13)>(20-A13)*8,IF(Q13>R13,D$1,I$1),"TBD")) -> TBD
A14: 11 | B14: =IF(AND(N13<>"",N13>3),B13,1-B13) -> 0 | C14: =IF(B14=0,D$1,I$1) -> Ravens | N14: {=IF(ABS((SUM(E14:H14)+INDEX(E14:H14,1,$D$4))-(SUM(I14:L14)+INDEX(I14:L14,1,$M$4)))>3,(1-2*B14)*((SUM(E14:H14)+INDEX(E14:H14,1,$D$4))-(SUM(I14:L14)+INDEX(I14:L14,1,$M$4))),"")} | O14: {=IF(N14<>"",N14,IF(B14=0,(E14+F14+IF($D$4<=2,INDEX(E14:H14,1,$D$4),0))-(K14+L14+IF($M$4>=3,INDEX(I14:L14,1,$M$4),0)),(I14+J14+IF($M$4<=2,INDEX(I14:L14,1,$M$4),0))-(G14+H14+IF($D$4>=3,INDEX(E14:H14,1,$D$4),0))))} -> 0 | P14: =IF(O14>3,"Onside Kick",IF(O14=3,"TD + 2PC",IF(O14=2,"Touchdown",IF(O14=1,"Field Goal",IF(O14>-2,"Punt",IF(O14=-2,"Safety",IF(O14=-3,"Pick Six","House Call"))))))) -> Punt | Q14: =IF(B14=0,Q13+IF(O14>1,IF(O14=3,8,7),IF(O14=1,3,0)),Q13+IF(O14>-2,0,IF(O14=-2,2,IF(O14=-3,6,7)))) -> 0 | R14: =IF(B14=0,R13+IF(O14>-2,0,IF(O14=-2,2,IF(O14=-3,6,7))),R13+IF(O14>1,IF(O14=3,8,7),IF(O14=1,3,0))) -> 0 | S14: =IF(OR(S13=D$1,S13=I$1),S13,IF(ABS(Q14-R14)>(20-A14)*8,IF(Q14>R14,D$1,I$1),"TBD")) -> TBD
A15: 12 | B15: =IF(AND(N14<>"",N14>3),B14,1-B14) -> 1 | C15: =IF(B15=0,D$1,I$1) -> Steelers | N15: {=IF(ABS((SUM(E15:H15)+INDEX(E15:H15,1,$D$4))-(SUM(I15:L15)+INDEX(I15:L15,1,$M$4)))>3,(1-2*B15)*((SUM(E15:H15)+INDEX(E15:H15,1,$D$4))-(SUM(I15:L15)+INDEX(I15:L15,1,$M$4))),"")} | O15: {=IF(N15<>"",N15,IF(B15=0,(E15+F15+IF($D$4<=2,INDEX(E15:H15,1,$D$4),0))-(K15+L15+IF($M$4>=3,INDEX(I15:L15,1,$M$4),0)),(I15+J15+IF($M$4<=2,INDEX(I15:L15,1,$M$4),0))-(G15+H15+IF($D$4>=3,INDEX(E15:H15,1,$D$4),0))))} -> 0 | P15: =IF(O15>3,"Onside Kick",IF(O15=3,"TD + 2PC",IF(O15=2,"Touchdown",IF(O15=1,"Field Goal",IF(O15>-2,"Punt",IF(O15=-2,"Safety",IF(O15=-3,"Pick Six","House Call"))))))) -> Punt | Q15: =IF(B15=0,Q14+IF(O15>1,IF(O15=3,8,7),IF(O15=1,3,0)),Q14+IF(O15>-2,0,IF(O15=-2,2,IF(O15=-3,6,7)))) -> 0 | R15: =IF(B15=0,R14+IF(O15>-2,0,IF(O15=-2,2,IF(O15=-3,6,7))),R14+IF(O15>1,IF(O15=3,8,7),IF(O15=1,3,0))) -> 0 | S15: =IF(OR(S14=D$1,S14=I$1),S14,IF(ABS(Q15-R15)>(20-A15)*8,IF(Q15>R15,D$1,I$1),"TBD")) -> TBD
A16: 13 | B16: =IF(AND(N15<>"",N15>3),B15,1-B15) -> 0 | C16: =IF(B16=0,D$1,I$1) -> Ravens | N16: {=IF(ABS((SUM(E16:H16)+INDEX(E16:H16,1,$D$4))-(SUM(I16:L16)+INDEX(I16:L16,1,$M$4)))>3,(1-2*B16)*((SUM(E16:H16)+INDEX(E16:H16,1,$D$4))-(SUM(I16:L16)+INDEX(I16:L16,1,$M$4))),"")} | O16: {=IF(N16<>"",N16,IF(B16=0,(E16+F16+IF($D$4<=2,INDEX(E16:H16,1,$D$4),0))-(K16+L16+IF($M$4>=3,INDEX(I16:L16,1,$M$4),0)),(I16+J16+IF($M$4<=2,INDEX(I16:L16,1,$M$4),0))-(G16+H16+IF($D$4>=3,INDEX(E16:H16,1,$D$4),0))))} -> 0 | P16: =IF(O16>3,"Onside Kick",IF(O16=3,"TD + 2PC",IF(O16=2,"Touchdown",IF(O16=1,"Field Goal",IF(O16>-2,"Punt",IF(O16=-2,"Safety",IF(O16=-3,"Pick Six","House Call"))))))) -> Punt | Q16: =IF(B16=0,Q15+IF(O16>1,IF(O16=3,8,7),IF(O16=1,3,0)),Q15+IF(O16>-2,0,IF(O16=-2,2,IF(O16=-3,6,7)))) -> 0 | R16: =IF(B16=0,R15+IF(O16>-2,0,IF(O16=-2,2,IF(O16=-3,6,7))),R15+IF(O16>1,IF(O16=3,8,7),IF(O16=1,3,0))) -> 0 | S16: =IF(OR(S15=D$1,S15=I$1),S15,IF(ABS(Q16-R16)>(20-A16)*8,IF(Q16>R16,D$1,I$1),"TBD")) -> TBD
A17: 14 | B17: =IF(AND(N16<>"",N16>3),B16,1-B16) -> 1 | C17: =IF(B17=0,D$1,I$1) -> Steelers | N17: {=IF(ABS((SUM(E17:H17)+INDEX(E17:H17,1,$D$4))-(SUM(I17:L17)+INDEX(I17:L17,1,$M$4)))>3,(1-2*B17)*((SUM(E17:H17)+INDEX(E17:H17,1,$D$4))-(SUM(I17:L17)+INDEX(I17:L17,1,$M$4))),"")} | O17: {=IF(N17<>"",N17,IF(B17=0,(E17+F17+IF($D$4<=2,INDEX(E17:H17,1,$D$4),0))-(K17+L17+IF($M$4>=3,INDEX(I17:L17,1,$M$4),0)),(I17+J17+IF($M$4<=2,INDEX(I17:L17,1,$M$4),0))-(G17+H17+IF($D$4>=3,INDEX(E17:H17,1,$D$4),0))))} -> 0 | P17: =IF(O17>3,"Onside Kick",IF(O17=3,"TD + 2PC",IF(O17=2,"Touchdown",IF(O17=1,"Field Goal",IF(O17>-2,"Punt",IF(O17=-2,"Safety",IF(O17=-3,"Pick Six","House Call"))))))) -> Punt | Q17: =IF(B17=0,Q16+IF(O17>1,IF(O17=3,8,7),IF(O17=1,3,0)),Q16+IF(O17>-2,0,IF(O17=-2,2,IF(O17=-3,6,7)))) -> 0 | R17: =IF(B17=0,R16+IF(O17>-2,0,IF(O17=-2,2,IF(O17=-3,6,7))),R16+IF(O17>1,IF(O17=3,8,7),IF(O17=1,3,0))) -> 0 | S17: =IF(OR(S16=D$1,S16=I$1),S16,IF(ABS(Q17-R17)>(20-A17)*8,IF(Q17>R17,D$1,I$1),"TBD")) -> TBD
A18: 15 | B18: =IF(AND(N17<>"",N17>3),B17,1-B17) -> 0 | C18: =IF(B18=0,D$1,I$1) -> Ravens | N18: {=IF(ABS((SUM(E18:H18)+INDEX(E18:H18,1,$D$4))-(SUM(I18:L18)+INDEX(I18:L18,1,$M$4)))>3,(1-2*B18)*((SUM(E18:H18)+INDEX(E18:H18,1,$D$4))-(SUM(I18:L18)+INDEX(I18:L18,1,$M$4))),"")} | O18: {=IF(N18<>"",N18,IF(B18=0,(E18+F18+IF($D$4<=2,INDEX(E18:H18,1,$D$4),0))-(K18+L18+IF($M$4>=3,INDEX(I18:L18,1,$M$4),0)),(I18+J18+IF($M$4<=2,INDEX(I18:L18,1,$M$4),0))-(G18+H18+IF($D$4>=3,INDEX(E18:H18,1,$D$4),0))))} -> 0 | P18: =IF(O18>3,"Onside Kick",IF(O18=3,"TD + 2PC",IF(O18=2,"Touchdown",IF(O18=1,"Field Goal",IF(O18>-2,"Punt",IF(O18=-2,"Safety",IF(O18=-3,"Pick Six","House Call"))))))) -> Punt | Q18: =IF(B18=0,Q17+IF(O18>1,IF(O18=3,8,7),IF(O18=1,3,0)),Q17+IF(O18>-2,0,IF(O18=-2,2,IF(O18=-3,6,7)))) -> 0 | R18: =IF(B18=0,R17+IF(O18>-2,0,IF(O18=-2,2,IF(O18=-3,6,7))),R17+IF(O18>1,IF(O18=3,8,7),IF(O18=1,3,0))) -> 0 | S18: =IF(OR(S17=D$1,S17=I$1),S17,IF(ABS(Q18-R18)>(20-A18)*8,IF(Q18>R18,D$1,I$1),"TBD")) -> TBD
A19: 16 | B19: =IF(AND(N18<>"",N18>3),B18,1-B18) -> 1 | C19: =IF(B19=0,D$1,I$1) -> Steelers | N19: {=IF(ABS((SUM(E19:H19)+INDEX(E19:H19,1,$D$4))-(SUM(I19:L19)+INDEX(I19:L19,1,$M$4)))>3,(1-2*B19)*((SUM(E19:H19)+INDEX(E19:H19,1,$D$4))-(SUM(I19:L19)+INDEX(I19:L19,1,$M$4))),"")} | O19: {=IF(N19<>"",N19,IF(B19=0,(E19+F19+IF($D$4<=2,INDEX(E19:H19,1,$D$4),0))-(K19+L19+IF($M$4>=3,INDEX(I19:L19,1,$M$4),0)),(I19+J19+IF($M$4<=2,INDEX(I19:L19,1,$M$4),0))-(G19+H19+IF($D$4>=3,INDEX(E19:H19,1,$D$4),0))))} -> 0 | P19: =IF(O19>3,"Onside Kick",IF(O19=3,"TD + 2PC",IF(O19=2,"Touchdown",IF(O19=1,"Field Goal",IF(O19>-2,"Punt",IF(O19=-2,"Safety",IF(O19=-3,"Pick Six","House Call"))))))) -> Punt | Q19: =IF(B19=0,Q18+IF(O19>1,IF(O19=3,8,7),IF(O19=1,3,0)),Q18+IF(O19>-2,0,IF(O19=-2,2,IF(O19=-3,6,7)))) -> 0 | R19: =IF(B19=0,R18+IF(O19>-2,0,IF(O19=-2,2,IF(O19=-3,6,7))),R18+IF(O19>1,IF(O19=3,8,7),IF(O19=1,3,0))) -> 0 | S19: =IF(OR(S18=D$1,S18=I$1),S18,IF(ABS(Q19-R19)>(20-A19)*8,IF(Q19>R19,D$1,I$1),"TBD")) -> TBD
A20: 17 | B20: =IF(AND(N19<>"",N19>3),B19,1-B19) -> 0 | C20: =IF(B20=0,D$1,I$1) -> Ravens | N20: {=IF(ABS((SUM(E20:H20)+INDEX(E20:H20,1,$D$4))-(SUM(I20:L20)+INDEX(I20:L20,1,$M$4)))>3,(1-2*B20)*((SUM(E20:H20)+INDEX(E20:H20,1,$D$4))-(SUM(I20:L20)+INDEX(I20:L20,1,$M$4))),"")} | O20: {=IF(N20<>"",N20,IF(B20=0,(E20+F20+IF($D$4<=2,INDEX(E20:H20,1,$D$4),0))-(K20+L20+IF($M$4>=3,INDEX(I20:L20,1,$M$4),0)),(I20+J20+IF($M$4<=2,INDEX(I20:L20,1,$M$4),0))-(G20+H20+IF($D$4>=3,INDEX(E20:H20,1,$D$4),0))))} -> 0 | P20: =IF(O20>3,"Onside Kick",IF(O20=3,"TD + 2PC",IF(O20=2,"Touchdown",IF(O20=1,"Field Goal",IF(O20>-2,"Punt",IF(O20=-2,"Safety",IF(O20=-3,"Pick Six","House Call"))))))) -> Punt | Q20: =IF(B20=0,Q19+IF(O20>1,IF(O20=3,8,7),IF(O20=1,3,0)),Q19+IF(O20>-2,0,IF(O20=-2,2,IF(O20=-3,6,7)))) -> 0 | R20: =IF(B20=0,R19+IF(O20>-2,0,IF(O20=-2,2,IF(O20=-3,6,7))),R19+IF(O20>1,IF(O20=3,8,7),IF(O20=1,3,0))) -> 0 | S20: =IF(OR(S19=D$1,S19=I$1),S19,IF(ABS(Q20-R20)>(20-A20)*8,IF(Q20>R20,D$1,I$1),"TBD")) -> TBD
A21: 18 | B21: =IF(AND(N20<>"",N20>3),B20,1-B20) -> 1 | C21: =IF(B21=0,D$1,I$1) -> Steelers | N21: {=IF(ABS((SUM(E21:H21)+INDEX(E21:H21,1,$D$4))-(SUM(I21:L21)+INDEX(I21:L21,1,$M$4)))>3,(1-2*B21)*((SUM(E21:H21)+INDEX(E21:H21,1,$D$4))-(SUM(I21:L21)+INDEX(I21:L21,1,$M$4))),"")} | O21: {=IF(N21<>"",N21,IF(B21=0,(E21+F21+IF($D$4<=2,INDEX(E21:H21,1,$D$4),0))-(K21+L21+IF($M$4>=3,INDEX(I21:L21,1,$M$4),0)),(I21+J21+IF($M$4<=2,INDEX(I21:L21,1,$M$4),0))-(G21+H21+IF($D$4>=3,INDEX(E21:H21,1,$D$4),0))))} -> 0 | P21: =IF(O21>3,"Onside Kick",IF(O21=3,"TD + 2PC",IF(O21=2,"Touchdown",IF(O21=1,"Field Goal",IF(O21>-2,"Punt",IF(O21=-2,"Safety",IF(O21=-3,"Pick Six","House Call"))))))) -> Punt | Q21: =IF(B21=0,Q20+IF(O21>1,IF(O21=3,8,7),IF(O21=1,3,0)),Q20+IF(O21>-2,0,IF(O21=-2,2,IF(O21=-3,6,7)))) -> 0 | R21: =IF(B21=0,R20+IF(O21>-2,0,IF(O21=-2,2,IF(O21=-3,6,7))),R20+IF(O21>1,IF(O21=3,8,7),IF(O21=1,3,0))) -> 0 | S21: =IF(OR(S20=D$1,S20=I$1),S20,IF(ABS(Q21-R21)>(20-A21)*8,IF(Q21>R21,D$1,I$1),"TBD")) -> TBD
A22: 19 | B22: =IF(AND(N21<>"",N21>3),B21,1-B21) -> 0 | C22: =IF(B22=0,D$1,I$1) -> Ravens | N22: {=IF(ABS((SUM(E22:H22)+INDEX(E22:H22,1,$D$4))-(SUM(I22:L22)+INDEX(I22:L22,1,$M$4)))>3,(1-2*B22)*((SUM(E22:H22)+INDEX(E22:H22,1,$D$4))-(SUM(I22:L22)+INDEX(I22:L22,1,$M$4))),"")} | O22: {=IF(N22<>"",N22,IF(B22=0,(E22+F22+IF($D$4<=2,INDEX(E22:H22,1,$D$4),0))-(K22+L22+IF($M$4>=3,INDEX(I22:L22,1,$M$4),0)),(I22+J22+IF($M$4<=2,INDEX(I22:L22,1,$M$4),0))-(G22+H22+IF($D$4>=3,INDEX(E22:H22,1,$D$4),0))))} -> 0 | P22: =IF(O22>3,"Onside Kick",IF(O22=3,"TD + 2PC",IF(O22=2,"Touchdown",IF(O22=1,"Field Goal",IF(O22>-2,"Punt",IF(O22=-2,"Safety",IF(O22=-3,"Pick Six","House Call"))))))) -> Punt | Q22: =IF(B22=0,Q21+IF(O22>1,IF(O22=3,8,7),IF(O22=1,3,0)),Q21+IF(O22>-2,0,IF(O22=-2,2,IF(O22=-3,6,7)))) -> 0 | R22: =IF(B22=0,R21+IF(O22>-2,0,IF(O22=-2,2,IF(O22=-3,6,7))),R21+IF(O22>1,IF(O22=3,8,7),IF(O22=1,3,0))) -> 0 | S22: =IF(OR(S21=D$1,S21=I$1),S21,IF(ABS(Q22-R22)>(20-A22)*8,IF(Q22>R22,D$1,I$1),"TBD")) -> TBD
A23: 20 | B23: =IF(AND(N22<>"",N22>3),B22,1-B22) -> 1 | C23: =IF(B23=0,D$1,I$1) -> Steelers | N23: {=IF(ABS((SUM(E23:H23)+INDEX(E23:H23,1,$D$4))-(SUM(I23:L23)+INDEX(I23:L23,1,$M$4)))>3,(1-2*B23)*((SUM(E23:H23)+INDEX(E23:H23,1,$D$4))-(SUM(I23:L23)+INDEX(I23:L23,1,$M$4))),"")} | O23: {=IF(N23<>"",N23,IF(B23=0,(E23+F23+IF($D$4<=2,INDEX(E23:H23,1,$D$4),0))-(K23+L23+IF($M$4>=3,INDEX(I23:L23,1,$M$4),0)),(I23+J23+IF($M$4<=2,INDEX(I23:L23,1,$M$4),0))-(G23+H23+IF($D$4>=3,INDEX(E23:H23,1,$D$4),0))))} -> 0 | P23: =IF(O23>3,"Onside Kick",IF(O23=3,"TD + 2PC",IF(O23=2,"Touchdown",IF(O23=1,"Field Goal",IF(O23>-2,"Punt",IF(O23=-2,"Safety",IF(O23=-3,"Pick Six","House Call"))))))) -> Punt | Q23: =IF(B23=0,Q22+IF(O23>1,IF(O23=3,8,7),IF(O23=1,3,0)),Q22+IF(O23>-2,0,IF(O23=-2,2,IF(O23=-3,6,7)))) -> 0 | R23: =IF(B23=0,R22+IF(O23>-2,0,IF(O23=-2,2,IF(O23=-3,6,7))),R22+IF(O23>1,IF(O23=3,8,7),IF(O23=1,3,0))) -> 0 | S23: =IF(OR(S22=D$1,S22=I$1),S22,IF(ABS(Q23-R23)>(20-A23)*8,IF(Q23>R23,D$1,I$1),"TBD")) -> TBD
A24: Overtime: 5 Random Songs. Onside/Safety/Pick ends it on Song 1, Sudden Death from Song 2
A25: 1 | B25: 0 | C25: =IF(B25=0,D$1,I$1) -> Ravens | D25: =D4 -> 1 | M25: =M4 -> 1 | N25: {=IF(ABS((SUM(E25:H25)+INDEX(E25:H25,1,$D$4))-(SUM(I25:L25)+INDEX(I25:L25,1,$M$4)))>3,(1-2*B25)*((SUM(E25:H25)+INDEX(E25:H25,1,$D$4))-(SUM(I25:L25)+INDEX(I25:L25,1,$M$4))),"")} | O25: {=IF(N25<>"",N25,IF(B25=0,(E25+F25+IF($D$4<=2,INDEX(E25:H25,1,$D$4),0))-(K25+L25+IF($M$4>=3,INDEX(I25:L25,1,$M$4),0)),(I25+J25+IF($M$4<=2,INDEX(I25:L25,1,$M$4),0))-(G25+H25+IF($D$4>=3,INDEX(E25:H25,1,$D$4),0))))} -> 0 | P25: =IF(O25>3,"Onside Kick",IF(O25=3,"TD + 2PC",IF(O25=2,"Touchdown",IF(O25=1,"Field Goal",IF(O25>-2,"Punt",IF(O25=-2,"Safety",IF(O25=-3,"Pick Six","House Call"))))))) -> Punt | Q25: =Q23+IF(O25>2,IF(O25=3,8,7),IF(O25=2,6,IF(O25=1,3,0))) -> 0 | R25: =R23+IF(O25>-2,0,IF(O25=-2,2,IF(O25=-3,6,7))) -> 0 | S25: =IF(OR(S23=D$1,S23=I$1),S23,IF(A25=1,IF(O25>3,$D$1,IF(O25<-1,$I$1,"TBD")),IF(Q25>R25,$D$1,IF(R25>Q25,$I$1,IF(A25=5,"Tie","TBD"))))) -> TBD
A26: 2 | B26: =IF(AND(N25<>"",N25>3),B25,1-B25) -> 1 | C26: =IF(B26=0,D$1,I$1) -> Steelers | N26: {=IF(ABS((SUM(E26:H26)+INDEX(E26:H26,1,$D$4))-(SUM(I26:L26)+INDEX(I26:L26,1,$M$4)))>3,(1-2*B26)*((SUM(E26:H26)+INDEX(E26:H26,1,$D$4))-(SUM(I26:L26)+INDEX(I26:L26,1,$M$4))),"")} | O26: {=IF(N26<>"",N26,IF(B26=0,(E26+F26+IF($D$4<=2,INDEX(E26:H26,1,$D$4),0))-(K26+L26+IF($M$4>=3,INDEX(I26:L26,1,$M$4),0)),(I26+J26+IF($M$4<=2,INDEX(I26:L26,1,$M$4),0))-(G26+H26+IF($D$4>=3,INDEX(E26:H26,1,$D$4),0))))} -> 0 | P26: =IF(O26>3,"Onside Kick",IF(O26=3,"TD + 2PC",IF(O26=2,"Touchdown",IF(O26=1,"Field Goal",IF(O26>-2,"Punt",IF(O26=-2,"Safety",IF(O26=-3,"Pick Six","House Call"))))))) -> Punt | Q26: =IF(B26=0,Q25+IF(O26>1,IF(O26=3,8,7),IF(O26=1,3,0)),Q25+IF(O26>-2,0,IF(O26=-2,2,IF(O26=-3,6,7)))) -> 0 | R26: =IF(B26=0,R25+IF(O26>-2,0,IF(O26=-2,2,IF(O26=-3,6,7))),R25+IF(O26>1,IF(O26=3,8,7),IF(O26=1,3,0))) -> 0 | S26: =IF(OR(S25=D$1,S25=I$1),S25,IF(A26=1,IF(O26>3,$D$1,IF(O26<-1,$I$1,"TBD")),IF(Q26>R26,$D$1,IF(R26>Q26,$I$1,IF(A26=5,"Tie","TBD"))))) -> TBD
A27: 3 | B27: =IF(AND(N26<>"",N26>3),B26,1-B26) -> 0 | C27: =IF(B27=0,D$1,I$1) -> Ravens | N27: {=IF(ABS((SUM(E27:H27)+INDEX(E27:H27,1,$D$4))-(SUM(I27:L27)+INDEX(I27:L27,1,$M$4)))>3,(1-2*B27)*((SUM(E27:H27)+INDEX(E27:H27,1,$D$4))-(SUM(I27:L27)+INDEX(I27:L27,1,$M$4))),"")} | O27: {=IF(N27<>"",N27,IF(B27=0,(E27+F27+IF($D$4<=2,INDEX(E27:H27,1,$D$4),0))-(K27+L27+IF($M$4>=3,INDEX(I27:L27,1,$M$4),0)),(I27+J27+IF($M$4<=2,INDEX(I27:L27,1,$M$4),0))-(G27+H27+IF($D$4>=3,INDEX(E27:H27,1,$D$4),0))))} -> 0 | P27: =IF(O27>3,"Onside Kick",IF(O27=3,"TD + 2PC",IF(O27=2,"Touchdown",IF(O27=1,"Field Goal",IF(O27>-2,"Punt",IF(O27=-2,"Safety",IF(O27=-3,"Pick Six","House Call"))))))) -> Punt | Q27: =IF(B27=0,Q26+IF(O27>1,IF(O27=3,8,7),IF(O27=1,3,0)),Q26+IF(O27>-2,0,IF(O27=-2,2,IF(O27=-3,6,7)))) -> 0 | R27: =IF(B27=0,R26+IF(O27>-2,0,IF(O27=-2,2,IF(O27=-3,6,7))),R26+IF(O27>1,IF(O27=3,8,7),IF(O27=1,3,0))) -> 0 | S27: =IF(OR(S26=D$1,S26=I$1),S26,IF(A27=1,IF(O27>3,$D$1,IF(O27<-1,$I$1,"TBD")),IF(Q27>R27,$D$1,IF(R27>Q27,$I$1,IF(A27=5,"Tie","TBD"))))) -> TBD
A28: 4 | B28: =IF(AND(N27<>"",N27>3),B27,1-B27) -> 1 | C28: =IF(B28=0,D$1,I$1) -> Steelers | N28: {=IF(ABS((SUM(E28:H28)+INDEX(E28:H28,1,$D$4))-(SUM(I28:L28)+INDEX(I28:L28,1,$M$4)))>3,(1-2*B28)*((SUM(E28:H28)+INDEX(E28:H28,1,$D$4))-(SUM(I28:L28)+INDEX(I28:L28,1,$M$4))),"")} | O28: {=IF(N28<>"",N28,IF(B28=0,(E28+F28+IF($D$4<=2,INDEX(E28:H28,1,$D$4),0))-(K28+L28+IF($M$4>=3,INDEX(I28:L28,1,$M$4),0)),(I28+J28+IF($M$4<=2,INDEX(I28:L28,1,$M$4),0))-(G28+H28+IF($D$4>=3,INDEX(E28:H28,1,$D$4),0))))} -> 0 | P28: =IF(O28>3,"Onside Kick",IF(O28=3,"TD + 2PC",IF(O28=2,"Touchdown",IF(O28=1,"Field Goal",IF(O28>-2,"Punt",IF(O28=-2,"Safety",IF(O28=-3,"Pick Six","House Call"))))))) -> Punt | Q28: =IF(B28=0,Q27+IF(O28>1,IF(O28=3,8,7),IF(O28=1,3,0)),Q27+IF(O28>-2,0,IF(O28=-2,2,IF(O28=-3,6,7)))) -> 0 | R28: =IF(B28=0,R27+IF(O28>-2,0,IF(O28=-2,2,IF(O28=-3,6,7))),R27+IF(O28>1,IF(O28=3,8,7),IF(O28=1,3,0))) -> 0 | S28: =IF(OR(S27=D$1,S27=I$1),S27,IF(A28=1,IF(O28>3,$D$1,IF(O28<-1,$I$1,"TBD")),IF(Q28>R28,$D$1,IF(R28>Q28,$I$1,IF(A28=5,"Tie","TBD"))))) -> TBD
A29: 5 | B29: =IF(AND(N28<>"",N28>3),B28,1-B28) -> 0 | C29: =IF(B29=0,D$1,I$1) -> Ravens | N29: {=IF(ABS((SUM(E29:H29)+INDEX(E29:H29,1,$D$4))-(SUM(I29:L29)+INDEX(I29:L29,1,$M$4)))>3,(1-2*B29)*((SUM(E29:H29)+INDEX(E29:H29,1,$D$4))-(SUM(I29:L29)+INDEX(I29:L29,1,$M$4))),"")} | O29: {=IF(N29<>"",N29,IF(B29=0,(E29+F29+IF($D$4<=2,INDEX(E29:H29,1,$D$4),0))-(K29+L29+IF($M$4>=3,INDEX(I29:L29,1,$M$4),0)),(I29+J29+IF($M$4<=2,INDEX(I29:L29,1,$M$4),0))-(G29+H29+IF($D$4>=3,INDEX(E29:H29,1,$D$4),0))))} -> 0 | P29: =IF(O29>3,"Onside Kick",IF(O29=3,"TD + 2PC",IF(O29=2,"Touchdown",IF(O29=1,"Field Goal",IF(O29>-2,"Punt",IF(O29=-2,"Safety",IF(O29=-3,"Pick Six","House Call"))))))) -> Punt | Q29: =IF(B29=0,Q28+IF(O29>1,IF(O29=3,8,7),IF(O29=1,3,0)),Q28+IF(O29>-2,0,IF(O29=-2,2,IF(O29=-3,6,7)))) -> 0 | R29: =IF(B29=0,R28+IF(O29>-2,0,IF(O29=-2,2,IF(O29=-3,6,7))),R28+IF(O29>1,IF(O29=3,8,7),IF(O29=1,3,0))) -> 0 | S29: =IF(OR(S28=D$1,S28=I$1),S28,IF(A29=1,IF(O29>3,$D$1,IF(O29<-1,$I$1,"TBD")),IF(Q29>R29,$D$1,IF(R29>Q29,$I$1,IF(A29=5,"Tie","TBD"))))) -> Tie

Sheet Game 3
A1: Song | B1: Poss. | C1: Poss. | D1: Ravens | I1: Steelers | N1: TDIFF | O1: DIFF | P1: Result | Q1: Score | S1: Winner
D2: C | E2: OP1 | F2: OP2 | G2: DP1 | H2: DP2 | I2: OP1 | J2: OP2 | K2: DP1 | L2: DP2 | M2: C | Q2: =D1 -> Ravens | R2: =I1 -> Steelers | U2: 1 | V2: Change E1 and I1 to the right Away and Home teams
A3: Regulation: 16 Watched Equal, 4 Random songs. Mercy Rule if Score Deficit > Remaining Songs × 8 | U3: 2 | V3: Fill Column E to L with 1 for whoever gets each song right
A4: 1 | B4: 0 | C4: =IF(B4=0,D$1,I$1) -> Ravens | D4: {=_xlfn.SWITCH(VLOOKUP(D1,Setup!A:C,3,FALSE),"OP1",1,"OP2",2,"DP1",3,"DP2",4,1)} -> 1 | M4: {=_xlfn.SWITCH(VLOOKUP(I1,Setup!A:C,3,FALSE),"OP1",1,"OP2",2,"DP1",3,"DP2",4,1)} -> 1 | N4: {=IF(ABS((SUM(E4:H4)+INDEX(E4:H4,1,$D$4))-(SUM(I4:L4)+INDEX(I4:L4,1,$M$4)))>3,(1-2*B4)*((SUM(E4:H4)+INDEX(E4:H4,1,$D$4))-(SUM(I4:L4)+INDEX(I4:L4,1,$M$4))),"")} | O4: {=IF(N4<>"",N4,IF(B4=0,(E4+F4+IF($D$4<=2,INDEX(E4:H4,1,$D$4),0))-(K4+L4+IF($M$4>=3,INDEX(I4:L4,1,$M$4),0)),(I4+J4+IF($M$4<=2,INDEX(I4:L4,1,$M$4),0))-(G4+H4+IF($D$4>=3,INDEX(E4:H4,1,$D$4),0))))} -> 0 | P4: =IF(O4>3,"Onside Kick",IF(O4=3,"TD + 2PC",IF(O4=2,"Touchdown",IF(O4=1,"Field Goal",IF(O4>-2,"Punt",IF(O4=-2,"Safety",IF(O4=-3,"Pick Six","House Call"))))))) -> Punt | Q4: =IF(O4>1,IF(O4=3,8,7),IF(O4=1,3,0)) -> 0 | R4: =IF(O4>-2,0,IF(O4=-2,2,IF(O4=-3,6,7))) -> 0 | S4: =IF(OR(S3=D$1,S3=I$1),S3,IF(ABS(Q4-R4)>(20-A4)*8,IF(Q4>R4,D$1,I$1),"TBD")) -> TBD | U4: 3 | V4: Continue playing until either happens:
A5: 2 | B5: =IF(AND(N4<>"",N4>3),B4,1-B4) -> 1 | C5: =IF(B5=0,D$1,I$1) -> Steelers | N5: {=IF(ABS((SUM(E5:H5)+INDEX(E5:H5,1,$D$4))-(SUM(I5:L5)+INDEX(I5:L5,1,$M$4)))>3,(1-2*B5)*((SUM(E5:H5)+INDEX(E5:H5,1,$D$4))-(SUM(I5:L5)+INDEX(I5:L5,1,$M$4))),"")} | O5: {=IF(N5<>"",N5,IF(B5=0,(E5+F5+IF($D$4<=2,INDEX(E5:H5,1,$D$4),0))-(K5+L5+IF($M$4>=3,INDEX(I5:L5,1,$M$4),0)),(I5+J5+IF($M$4<=2,INDEX(I5:L5,1,$M$4),0))-(G5+H5+IF($D$4>=3,INDEX(E5:H5,1,$D$4),0))))} -> 0 | P5: =IF(O5>3,"Onside Kick",IF(O5=3,"TD + 2PC",IF(O5=2,"Touchdown",IF(O5=1,"Field Goal",IF(O5>-2,"Punt",IF(O5=-2,"Safety",IF(O5=-3,"Pick Six","House Call"))))))) -> Punt | Q5: =IF(B5=0,Q4+IF(O5>1,IF(O5=3,8,7),IF(O5=1,3,0)),Q4+IF(O5>-2,0,IF(O5=-2,2,IF(O5=-3,6,7)))) -> 0 | R5: =IF(B5=0,R4+IF(O5>-2,0,IF(O5=-2,2,IF(O5=-3,6,7))),R4+IF(O5>1,IF(O5=3,8,7),IF(O5=1,3,0))) -> 0 | S5: =IF(OR(S4=D$1,S4=I$1),S4,IF(ABS(Q5-R5)>(20-A5)*8,IF(Q5>R5,D$1,I$1),"TBD")) -> TBD | V5: 1 | W5: You run out of songs, or
A6: 3 | B6: =IF(AND(N5<>"",N5>3),B5,1-B5) -> 0 | C6: =IF(B6=0,D$1,I$1) -> Ravens | N6: {=IF(ABS((SUM(E6:H6)+INDEX(E6:H6,1,$D$4))-(SUM(I6:L6)+INDEX(I6:L6,1,$M$4)))>3,(1-2*B6)*((SUM(E6:H6)+INDEX(E6:H6,1,$D$4))-(SUM(I6:L6)+INDEX(I6:L6,1,$M$4))),"")} | O6: {=IF(N6<>"",N6,IF(B6=0,(E6+F6+IF($D$4<=2,INDEX(E6:H6,1,$D$4),0))-(K6+L6+IF($M$4>=3,INDEX(I6:L6,1,$M$4),0)),(I6+J6+IF($M$4<=2,INDEX(I6:L6,1,$M$4),0))-(G6+H6+IF($D$4>=3,INDEX(E6:H6,1,$D$4),0))))} -> 0 | P6: =IF(O6>3,"Onside Kick",IF(O6=3,"TD + 2PC",IF(O6=2,"Touchdown",IF(O6=1,"Field Goal",IF(O6>-2,"Punt",IF(O6=-2,"Safety",IF(O6=-3,"Pick Six","House Call"))))))) -> Punt | Q6: =IF(B6=0,Q5+IF(O6>1,IF(O6=3,8,7),IF(O6=1,3,0)),Q5+IF(O6>-2,0,IF(O6=-2,2,IF(O6=-3,6,7)))) -> 0 | R6: =IF(B6=0,R5+IF(O6>-2,0,IF(O6=-2,2,IF(O6=-3,6,7))),R5+IF(O6>1,IF(O6=3,8,7),IF(O6=1,3,0))) -> 0 | S6: =IF(OR(S5=D$1,S5=I$1),S5,IF(ABS(Q6-R6)>(20-A6)*8,IF(Q6>R6,D$1,I$1),"TBD")) -> TBD | V6: 2 | W6: Winner column on current Song row is not TBD
A7: 4 | B7: =IF(AND(N6<>"",N6>3),B6,1-B6) -> 1 | C7: =IF(B7=0,D$1,I$1) -> Steelers | N7: {=IF(ABS((SUM(E7:H7)+INDEX(E7:H7,1,$D$4))-(SUM(I7:L7)+INDEX(I7:L7,1,$M$4)))>3,(1-2*B7)*((SUM(E7:H7)+INDEX(E7:H7,1,$D$4))-(SUM(I7:L7)+INDEX(I7:L7,1,$M$4))),"")} | O7: {=IF(N7<>"",N7,IF(B7=0,(E7+F7+IF($D$4<=2,INDEX(E7:H7,1,$D$4),0))-(K7+L7+IF($M$4>=3,INDEX(I7:L7,1,$M$4),0)),(I7+J7+IF($M$4<=2,INDEX(I7:L7,1,$M$4),0))-(G7+H7+IF($D$4>=3,INDEX(E7:H7,1,$D$4),0))))} -> 0 | P7: =IF(O7>3,"Onside Kick",IF(O7=3,"TD + 2PC",IF(O7=2,"Touchdown",IF(O7=1,"Field Goal",IF(O7>-2,"Punt",IF(O7=-2,"Safety",IF(O7=-3,"Pick Six","House Call"))))))) -> Punt | Q7: =IF(B7=0,Q6+IF(O7>1,IF(O7=3,8,7),IF(O7=1,3,0)),Q6+IF(O7>-2,0,IF(O7=-2,2,IF(O7=-3,6,7)))) -> 0 | R7: =IF(B7=0,R6+IF(O7>-2,0,IF(O7=-2,2,IF(O7=-3,6,7))),R6+IF(O7>1,IF(O7=3,8,7),IF(O7=1,3,0))) -> 0 | S7: =IF(OR(S6=D$1,S6=I$1),S6,IF(ABS(Q7-R7)>(20-A7)*8,IF(Q7>R7,D$1,I$1),"TBD")) -> TBD | U7: 4 | V7: Continue to the next Game scoresheet
A8: 5 | B8: =IF(AND(N7<>"",N7>3),B7,1-B7) -> 0 | C8: =IF(B8=0,D$1,I$1) -> Ravens | N8: {=IF(ABS((SUM(E8:H8)+INDEX(E8:H8,1,$D$4))-(SUM(I8:L8)+INDEX(I8:L8,1,$M$4)))>3,(1-2*B8)*((SUM(E8:H8)+INDEX(E8:H8,1,$D$4))-(SUM(I8:L8)+INDEX(I8:L8,1,$M$4))),"")} | O8: {=IF(N8<>"",N8,IF(B8=0,(E8+F8+IF($D$4<=2,INDEX(E8:H8,1,$D$4),0))-(K8+L8+IF($M$4>=3,INDEX(I8:L8,1,$M$4),0)),(I8+J8+IF($M$4<=2,INDEX(I8:L8,1,$M$4),0))-(G8+H8+IF($D$4>=3,INDEX(E8:H8,1,$D$4),0))))} -> 0 | P8: =IF(O8>3,"Onside Kick",IF(O8=3,"TD + 2PC",IF(O8=2,"Touchdown",IF(O8=1,"Field Goal",IF(O8>-2,"Punt",IF(O8=-2,"Safety",IF(O8=-3,"Pick Six","House Call"))))))) -> Punt | Q8: =IF(B8=0,Q7+IF(O8>1,IF(O8=3,8,7),IF(O8=1,3,0)),Q7+IF(O8>-2,0,IF(O8=-2,2,IF(O8=-3,6,7)))) -> 0 | R8: =IF(B8=0,R7+IF(O8>-2,0,IF(O8=-2,2,IF(O8=-3,6,7))),R7+IF(O8>1,IF(O8=3,8,7),IF(O8=1,3,0))) -> 0 | S8: =IF(OR(S7=D$1,S7=I$1),S7,IF(ABS(Q8-R8)>(20-A8)*8,IF(Q8>R8,D$1,I$1),"TBD")) -> TBD | V8: Swap Away and Home if you play the same team again
A9: 6 | B9: =IF(AND(N8<>"",N8>3),B8,1-B8) -> 1 | C9: =IF(B9=0,D$1,I$1) -> Steelers | N9: {=IF(ABS((SUM(E9:H9)+INDEX(E9:H9,1,$D$4))-(SUM(I9:L9)+INDEX(I9:L9,1,$M$4)))>3,(1-2*B9)*((SUM(E9:H9)+INDEX(E9:H9,1,$D$4))-(SUM(I9:L9)+INDEX(I9:L9,1,$M$4))),"")} | O9: {=IF(N9<>"",N9,IF(B9=0,(E9+F9+IF($D$4<=2,INDEX(E9:H9,1,$D$4),0))-(K9+L9+IF($M$4>=3,INDEX(I9:L9,1,$M$4),0)),(I9+J9+IF($M$4<=2,INDEX(I9:L9,1,$M$4),0))-(G9+H9+IF($D$4>=3,INDEX(E9:H9,1,$D$4),0))))} -> 0 | P9: =IF(O9>3,"Onside Kick",IF(O9=3,"TD + 2PC",IF(O9=2,"Touchdown",IF(O9=1,"Field Goal",IF(O9>-2,"Punt",IF(O9=-2,"Safety",IF(O9=-3,"Pick Six","House Call"))))))) -> Punt | Q9: =IF(B9=0,Q8+IF(O9>1,IF(O9=3,8,7),IF(O9=1,3,0)),Q8+IF(O9>-2,0,IF(O9=-2,2,IF(O9=-3,6,7)))) -> 0 | R9: =IF(B9=0,R8+IF(O9>-2,0,IF(O9=-2,2,IF(O9=-3,6,7))),R8+IF(O9>1,IF(O9=3,8,7),IF(O9=1,3,0))) -> 0 | S9: =IF(OR(S8=D$1,S8=I$1),S8,IF(ABS(Q9-R9)>(20-A9)*8,IF(Q9>R9,D$1,I$1),"TBD")) -> TBD | U9: 5 | V9: Report the link to your copy after the last game
A10: 7 | B10: =IF(AND(N9<>"",N9>3),B9,1-B9) -> 0 | C10: =IF(B10=0,D$1,I$1) -> Ravens | N10: {=IF(ABS((SUM(E10:H10)+INDEX(E10:H10,1,$D$4))-(SUM(I10:L10)+INDEX(I10:L10,1,$M$4)))>3,(1-2*B10)*((SUM(E10:H10)+INDEX(E10:H10,1,$D$4))-(SUM(I10:L10)+INDEX(I10:L10,1,$M$4))),"")} | O10: {=IF(N10<>"",N10,IF(B10=0,(E10+F10+IF($D$4<=2,INDEX(E10:H10,1,$D$4),0))-(K10+L10+IF($M$4>=3,INDEX(I10:L10,1,$M$4),0)),(I10+J10+IF($M$4<=2,INDEX(I10:L10,1,$M$4),0))-(G10+H10+IF($D$4>=3,INDEX(E10:H10,1,$D$4),0))))} -> 0 | P10: =IF(O10>3,"Onside Kick",IF(O10=3,"TD + 2PC",IF(O10=2,"Touchdown",IF(O10=1,"Field Goal",IF(O10>-2,"Punt",IF(O10=-2,"Safety",IF(O10=-3,"Pick Six","House Call"))))))) -> Punt | Q10: =IF(B10=0,Q9+IF(O10>1,IF(O10=3,8,7),IF(O10=1,3,0)),Q9+IF(O10>-2,0,IF(O10=-2,2,IF(O10=-3,6,7)))) -> 0 | R10: =IF(B10=0,R9+IF(O10>-2,0,IF(O10=-2,2,IF(O10=-3,6,7))),R9+IF(O10>1,IF(O10=3,8,7),IF(O10=1,3,0))) -> 0 | S10: =IF(OR(S9=D$1,S9=I$1),S9,IF(ABS(Q10-R10)>(20-A10)*8,IF(Q10>R10,D$1,I$1),"TBD")) -> TBD | U10: If you get a Protection Error, you probably shouldn't touch that cell
